Workbook

Sheet START HERE
A1: Autoimmune Pattern & Care Tracker
A2: DEMO VERSION — fictional sample data is included so you can see how the tracker works.
A3: A customizable workbook for tracking symptoms, flares, treatments, nutrition/AIP, labs, care access, and patterns over time.
A5: Start in three steps
A6: 1. Open Customize Lists and personalize any dropdown choices you want. Each list includes blank rows for your own options.
A7: 2. Open Customize and tailor the symptom library so it reflects what you actually want to track.
A8: 3. Start with Daily Check-In. Add detail in the other logs only when it is useful to you.
A10: A low-effort workflow
A11: 1. QUICK DAILY | B11: Daily Check-In — One row per day for symptom burden, pain, fatigue, energy, sleep, function, stress, and broad system impact.
A12: 2. ADD DETAIL WHEN NEEDED | B12: Use the symptom, flare, treatment, food, trigger, lab, or access logs when something changes or deserves its own record.
A13: 3. REVIEW PATTERNS | B13: Use the Dashboard and your detailed logs to prepare for appointments, compare time periods, or simply understand what has been changing.
A15: Make it yours
A16: DROPDOWNS — Open Customize Lists. Replace any blank row in a list table with your own wording and the dropdowns will use it.
A17: SYMPTOMS — Add, rename, or remove symptoms and categories on Customize so the tracker fits your experience.
A18: THEME — In Excel, choose Page Layout → Themes or Colors. Theme-linked titles, headers, cards, tables, and charts will update.
A19: TRACKING STYLE — Use only the sheets that help you. The workbook is designed to work whether you track a little or a lot.
A22: Workbook map
A23: Sheet | B23: Use it for
A24: START HERE | B24: Quick setup, customization steps, and workbook map.
A25: Dashboard | B25: Review-window summary and trend chart.
A26: Profile & Goals | B26: Baseline, current status, goals, and your own definitions of flare and doing well.
A27: Customize | B27: Symptom library and personal symptom/category setup.
A28: Customize Lists | B28: Edit every dropdown list and add your own choices.
A29: Daily Check-In | B29: Fast daily snapshot.
A30: Symptom Log | B30: Detailed symptom-level entries.
A31: Flare Log | B31: Distinct flare episodes and functional impact.
A32: Treatments | B32: Medication, infusion, injection, supplement, therapy, device, nutrition, or lifestyle plan.
A33: Treatment Events | B33: Actual doses/events, missed or held treatment, response, and side effects.
A34: AIP & Nutrition | B34: AIP phase, food/reintroduction observations, and nutrition-related changes.
... A39: Diagnostic Journey | B39: Track conditions or clinical questions discussed across providers and time.

Sheet Profile & Goals
A1: Profile & Goals
A4: Field | B4: Your information | D4: Tracking goals
A5: Name / alias (optional) | B5: Jordan Sample (fictional) | D5: Goal | E5: Use? | F5: Notes
A6: Tracking start date | B6: 46275 | D6: Identify symptom patterns | E6: Yes | F6: Compare daily burden with sleep, sun, stress, and treatment timing
A7: Current status | B7: Established diagnosis | D7: Document a flare | E7: Yes | F7: Capture a flare episode from start through recovery
A8: Primary diagnosis / suspected condition | B8: Systemic autoimmune / inflammatory condition (sample) | D8: Track response to treatment | E8: Yes | F8: Compare symptoms before and after treatment
A9: Other diagnoses / suspected conditions | B9: Possible inflammatory arthritis; migraine history | D9: Track side effects | E9: Yes | F9: Record possible medication side effects separately from disease symptoms
A10: Main care team / specialties | B10: Primary care; rheumatology; dermatology | D10: Track symptoms while untreated/unmedicated | E10: No | F10: Not the main goal in this fictional example
A11: Main reason for tracking | B11: Understand flare patterns and treatment response | D11: Prepare for diagnosis or specialist evaluation | E11: No | F11: Diagnosis is already established in this sample
A12: What a typical/baseline day looks like | B12: Pain 2–3, fatigue 3–4, generally able to work and do normal activities | D12: Track AIP / food reintroduction | E12: Yes | F12: Demonstrate an AIP-style food reintroduction log
A13: How I define a flare | B13: A sustained increase in several symptoms that reduces normal function for more than a day | D13: Track lifestyle or environmental triggers | E13: Yes | F13: Track sleep, UV, activity, and infection context
A14: How I define remission / low activity / 'doing well' | B14: Symptoms mostly 0–3 with normal daily function | D14: Document insurance/cost/access barriers | E14: Yes | F14: Show how access delays can be documented
A15: Top 3 symptoms I most want to understand | B15: Fatigue; joint pain; brain fog | D15: Prepare for appointments | E15: Yes | F15: Prepare a concise trend summary for a follow-up visit
A16: Current treatment context | B16: Maintenance medication active; infusion delayed by insurance review during sample period | D16: Monitor remission / lower activity
A17: Known care-access barriers | B17: Prior authorization delays for infusion
A18: Important allergies / intolerances / contraindications | B18: Sulfa allergy (sample only)

Sheet Customize
A1: Customize Your Tracker
A3: Use these examples as a starting point. Add, rename, or delete symptoms and categories so the tracker reflects what you want to follow.
A5: Symptom / experience | B5: Category | C5: Track regularly? | D5: Personal notes / what it means for me | F5: Dropdown choices | G5: Where to edit | H5: How it works
A6: Fatigue / exhaustion | B6: General / systemic | F6: All workbook dropdowns | G6: Customize Lists | H6: Replace a blank row in the matching list table with your own option.
A7: Post-exertional worsening | B7: General / systemic | F7: 0–10 Scale | G7: Customize Lists | H7: Keep these entries numeric if you want Dashboard averages to calculate.
A8: Malaise / flu-like feeling | B8: General / systemic | F8: Theme colors | G8: Page Layout → Themes / Colors | H8: Choose any Excel theme or color set to personalize the workbook.
A9: Low-grade fever / feeling feverish | B9: General / systemic
A10: Chills | B10: General / systemic
A11: Night sweats | B11: General / systemic
A12: Unintentional weight change | B12: General / systemic
A13: Joint pain | B13: Musculoskeletal
A14: Morning stiffness | B14: Musculoskeletal
A15: Joint swelling | B15: Musculoskeletal
A16: Muscle pain | B16: Musculoskeletal
A17: Muscle weakness | B17: Musculoskeletal
A18: Tendon / enthesis pain | B18: Musculoskeletal
A19: Back / neck pain | B19: Musculoskeletal
A20: Reduced grip strength | B20: Musculoskeletal
... A88: Other / custom | B88: Custom

Sheet Daily Check-In
A1: Daily Check-In
A3: One row per day. The goal is consistency, not perfection. Leave anything blank that makes tracking too burdensome. Use Symptom Log when a symptom needs more detail.
A5: Date | B5: Day Type | C5: Overall Symptom Burden 0–10 | D5: Pain 0–10 | E5: Fatigue 0–10 | F5: Energy 0–10 | G5: Brain Fog 0–10 | H5: Sleep Hours | I5: Sleep Quality 0–10 | J5: Function 0–10 | K5: Stress 0–10 | L5: GI Impact 0–10 | M5: Skin / Mucosal 0–10 | N5: Joint / Muscle 0–10 | O5: Dryness 0–10 | P5: Temp / Autonomic 0–10 | Q5: Ill / Infection? | R5: Hormonal / Cycle Context | S5: New / Unusual Symptom? | T5: Treatment Taken as Planned? | U5: AIP Phase | V5: Notes
A6: 46275 | B6: Typical | C6: 3 | D6: 2 | E6: 4 | F6: 6 | G6: 2 | H6: 7.2 | I6: 7 | J6: 8 | K6: 4 | L6: 1 | M6: 2 | N6: 3 | O6: 2 | P6: 2 | Q6: No | S6: No | T6: Yes | U6: Elimination
A7: 46276 | B7: Typical | C7: 3 | D7: 2 | E7: 4 | F7: 6 | G7: 2 | H7: 7 | I7: 7 | J7: 8 | K7: 4 | L7: 1 | M7: 2 | N7: 3 | O7: 2 | P7: 2 | Q7: No | S7: No | T7: Yes | U7: Elimination
A8: 46277 | B8: Typical | C8: 4 | D8: 3 | E8: 5 | F8: 5 | G8: 3 | H8: 6.5 | I8: 6 | J8: 7 | K8: 5 | L8: 1 | M8: 2 | N8: 4 | O8: 2 | P8: 2 | Q8: No | S8: No | T8: Yes | U8: Elimination
A9: 46278 | B9: Typical | C9: 3 | D9: 2 | E9: 4 | F9: 6 | G9: 2 | H9: 7.5 | I9: 8 | J9: 8 | K9: 3 | L9: 1 | M9: 1 | N9: 3 | O9: 2 | P9: 1 | Q9: No | S9: No | T9: Yes | U9: Elimination
A10: 46279 | B10: Typical | C10: 3 | D10: 2 | E10: 4 | F10: 6 | G10: 2 | H10: 7.3 | I10: 7 | J10: 8 | K10: 4 | L10: 1 | M10: 2 | N10: 3 | O10: 2 | P10: 2 | Q10: No | S10: No | T10: Yes | U10: Elimination
A11: 46280 | B11: Typical | C11: 4 | D11: 3 | E11: 5 | F11: 5 | G11: 3 | H11: 6.8 | I11: 6 | J11: 7 | K11: 6 | L11: 2 | M11: 2 | N11: 4 | O11: 2 | P11: 2 | Q11: No | S11: No | T11: Yes | U11: Elimination
A12: 46281 | B12: Typical | C12: 4 | D12: 3 | E12: 5 | F12: 5 | G12: 3 | H12: 6.2 | I12: 5 | J12: 7 | K12: 6 | L12: 2 | M12: 3 | N12: 4 | O12: 3 | P12: 2 | Q12: No | S12: No | T12: Yes | U12: Elimination
A13: 46282 | B13: Typical | C13: 5 | D13: 4 | E13: 6 | F13: 4 | G13: 4 | H13: 5.8 | I13: 4 | J13: 6 | K13: 7 | L13: 2 | M13: 4 | N13: 5 | O13: 3 | P13: 3 | Q13: No | S13: No | T13: Yes | U13: Elimination | V13: Long outdoor afternoon; more sun exposure than usual.
A14: 46283 | B14: Typical | C14: 6 | D14: 5 | E14: 7 | F14: 3 | G14: 5 | H14: 5.2 | I14: 4 | J14: 5 | K14: 7 | L14: 3 | M14: 5 | N14: 6 | O14: 4 | P14: 4 | Q14: Unsure | S14: No | T14: Yes | U14: Elimination
A15: 46284 | B15: Flare | C15: 8 | D15: 7 | E15: 8 | F15: 2 | G15: 7 | H15: 4.8 | I15: 3 | J15: 3 | K15: 8 | L15: 4 | M15: 6 | N15: 8 | O15: 5 | P15: 5 | Q15: No | S15: Yes | T15: Yes | U15: Elimination | V15: Flare began with marked fatigue, joint pain, rash, and brain fog.
A16: 46285 | B16: Flare | C16: 8 | D16: 8 | E16: 9 | F16: 2 | G16: 7 | H16: 4.5 | I16: 2 | J16: 2 | K16: 8 | L16: 5 | M16: 6 | N16: 8 | O16: 6 | P16: 6 | Q16: No | S16: Yes | T16: Partly | U16: Elimination
A17: 46286 | B17: Flare | C17: 9 | D17: 8 | E17: 9 | F17: 1 | G17: 8 | H17: 4.2 | I17: 2 | J17: 2 | K17: 7 | L17: 5 | M17: 7 | N17: 9 | O17: 6 | P17: 6 | Q17: No | R17: Cycle week / hormonal change noted | S17: No | T17: No | U17: Elimination | V17: Infusion delayed while prior authorization was pending.
A18: 46287 | B18: Flare | C18: 8 | D18: 7 | E18: 8 | F18: 2 | G18: 7 | H18: 5 | I18: 3 | J18: 3 | K18: 6 | L18: 4 | M18: 6 | N18: 8 | O18: 5 | P18: 5 | Q18: No | R18: Cycle week / hormonal change noted | S18: No | T18: No | U18: Elimination
A19: 46288 | B19: Flare | C19: 7 | D19: 6 | E19: 8 | F19: 3 | G19: 6 | H19: 5.5 | I19: 4 | J19: 4 | K19: 6 | L19: 3 | M19: 5 | N19: 7 | O19: 5 | P19: 4 | Q19: No | R19: Cycle week / hormonal change noted | S19: No | T19: Partly | U19: Elimination
A20: 46289 | B20: Flare | C20: 7 | D20: 6 | E20: 7 | F20: 3 | G20: 5 | H20: 6 | I20: 5 | J20: 5 | K20: 5 | L20: 3 | M20: 4 | N20: 7 | O20: 4 | P20: 4 | Q20: No | S20: No | T20: Yes | U20: Elimination | V20: Symptoms beginning to ease; pacing and extra rest helped.
A21: 46290 | B21: Recovery | C21: 6 | D21: 5 | E21: 7 | F21: 4 | G21: 5 | H21: 6.2 | I21: 5 | J21: 6 | K21: 5 | L21: 2 | M21: 4 | N21: 6 | O21: 4 | P21: 3 | Q21: No | S21: No | T21: Yes | U21: Elimination
A22: 46291 | B22: Recovery | C22: 6 | D22: 5 | E22: 6 | F22: 4 | G22: 4 | H22: 6.5 | I22: 6 | J22: 6 | K22: 4 | L22: 2 | M22: 3 | N22: 6 | O22: 3 | P22: 3 | Q22: No | S22: No | T22: Yes | U22: Elimination
A23: 46292 | B23: Recovery | C23: 5 | D23: 4 | E23: 6 | F23: 5 | G23: 4 | H23: 6.8 | I23: 6 | J23: 7 | K23: 4 | L23: 2 | M23: 3 | N23: 5 | O23: 3 | P23: 2 | Q23: No | S23: No | T23: Yes | U23: Elimination
A24: 46293 | B24: Recovery | C24: 5 | D24: 4 | E24: 5 | F24: 5 | G24: 3 | H24: 7 | I24: 7 | J24: 7 | K24: 4 | L24: 2 | M24: 3 | N24: 5 | O24: 3 | P24: 2 | Q24: No | S24: No | T24: Yes | U24: Reintroduction | V24: Close to baseline; resumed light activity.
A25: 46294 | B25: Typical | C25: 4 | D25: 3 | E25: 5 | F25: 6 | G25: 3 | H25: 7.2 | I25: 7 | J25: 8 | K25: 3 | L25: 1 | M25: 2 | N25: 4 | O25: 2 | P25: 2 | Q25: No | S25: No | T25: Yes | U25: Reintroduction
A26: 46295 | B26: Typical | C26: 4 | D26: 3 | E26: 4 | F26: 6 | G26: 2 | H26: 7.5 | I26: 8 | J26: 8 | K26: 3 | L26: 1 | M26: 2 | N26: 4 | O26: 2 | P26: 1 | Q26: No | S26: No | T26: Yes | U26: Reintroduction
A27: 46296 | B27: Better than usual | C27: 3 | D27: 2 | E27: 4 | F27: 7 | G27: 2 | H27: 7.4 | I27: 8 | J27: 9 | K27: 3 | L27: 1 | M27: 2 | N27: 3 | O27: 2 | P27: 1 | Q27: No | S27: No | T27: Yes | U27: Reintroduction
A28: 46297 | B28: Better than usual | C28: 3 | D28: 2 | E28: 4 | F28: 7 | G28: 2 | H28: 7.6 | I28: 8 | J28: 9 | K28: 3 | L28: 1 | M28: 2 | N28: 3 | O28: 2 | P28: 1 | Q28: No | S28: No | T28: Yes | U28: Reintroduction
A29: 46298 | B29: Typical | C29: 4 | D29: 3 | E29: 4 | F29: 6 | G29: 3 | H29: 7 | I29: 7 | J29: 8 | K29: 4 | L29: 1 | M29: 2 | N29: 4 | O29: 2 | P29: 2 | Q29: No | S29: No | T29: Yes | U29: Reintroduction | V29: Reintroduced one food; monitored for change.
A30: 46299 | B30: Better than usual | C30: 3 | D30: 2 | E30: 4 | F30: 7 | G30: 2 | H30: 7.5 | I30: 8 | J30: 9 | K30: 3 | L30: 1 | M30: 2 | N30: 3 | O30: 2 | P30: 1 | Q30: No | S30: No | T30: Yes | U30: Reintroduction | V30: No clear symptom increase after reintroduction.
A31: 46300 | B31: Better than usual | C31: 3 | D31: 2 | E31: 3 | F31: 7 | G31: 2 | H31: 7.8 | I31: 8 | J31: 9 | K31: 3 | L31: 1 | M31: 1 | N31: 3 | O31: 2 | P31: 1 | Q31: No | S31: No | T31: Yes | U31: Personalized / maintenance
A32: 46301 | B32: Better than usual | C32: 3 | D32: 2 | E32: 3 | F32: 7 | G32: 2 | H32: 7.4 | I32: 8 | J32: 9 | K32: 4 | L32: 1 | M32: 1 | N32: 3 | O32: 2 | P32: 1 | Q32: No | S32: No | T32: Yes | U32: Personalized / maintenance
A33: 46302 | B33: Typical | C33: 3 | D33: 2 | E33: 4 | F33: 6 | G33: 2 | H33: 7.2 | I33: 7 | J33: 8 | K33: 4 | L33: 1 | M33: 2 | N33: 3 | O33: 2 | P33: 2 | Q33: No | S33: No | T33: Yes | U33: Personalized / maintenance

Sheet Symptom Log
A1: Symptom Log
A3: Use this for unlimited symptom-level detail: new, unusual, severe, changing, intermittent, or treatment-related symptoms. One row per symptom event.
A5: Date | B5: Time | C5: Symptom | D5: Category | E5: Severity 0–10 | F5: Interference 0–10 | G5: Duration / Pattern | H5: Change | I5: Body Location | J5: Onset / Timing | K5: Possible Trigger / Context | L5: Action / Treatment | M5: Response / What Helped | N5: New Symptom? | O5: Follow-Up Needed? | P5: Notes
A6: 46283 | B6: 18:30 | C6: Facial redness / rash | D6: Skin | E6: 6 | F6: 4 | G6: Several hours | H6: Worse | I6: Face | J6: After outdoor activity | K6: UV / sun | L6: Cool shower; shade; rest | M6: Improved by evening | N6: No | O6: No | P6: Noted before flare escalation
A7: 46284 | B7: 08:00 | C7: Joint pain and stiffness | D7: Joint / muscle | E7: 7 | F7: 7 | G7: All day | H7: Worse | I7: Hands, knees | J7: On waking | K7: Poor sleep; flare onset | L7: Heat; pacing; prescribed medication | M7: Partial relief | N7: No | O7: Yes | P7: Interfered with normal morning routine
A8: 46284 | B8: 10:00 | C8: Brain fog | D8: Neurologic / cognitive | E8: 7 | F8: 6 | G8: Most of day | H8: Worse | J8: During work tasks | K8: Flare onset | L8: Reduced task load; breaks | M8: Some improvement with rest | N8: No | O8: No | P8: Difficulty finding words and concentrating
A9: 46285 | B9: 07:30 | C9: Fatigue | D9: Constitutional | E9: 9 | F9: 9 | G9: All day | H9: Worse | I9: Whole body | J9: On waking | K9: Flare | L9: Rest; hydration; pacing | M9: Minimal same-day improvement | N9: No | O9: Yes | P9: Needed help with errands
A10: 46285 | B10: 13:00 | C10: Mouth sore | D10: Mucosal | E10: 7 | F10: 4 | G10: 2 days | H10: New | I10: Inside lower lip | J10: During flare | K10: Unknown | L10: Symptom care | M10: Resolved over 48 hours | N10: Yes | O10: No | P10: First one this month
A11: 46286 | B11: 09:00 | C11: Joint pain and stiffness | D11: Joint / muscle | E11: 8 | F11: 8 | G11: All day | H11: Same | I11: Hands, knees, ankles | J11: Morning | K11: Infusion delayed | L11: Heat; pacing | M11: Partial relief | N11: No | O11: Yes | P11: Peak joint symptom day
A12: 46287 | B12: 15:00 | C12: Headache | D12: Neurologic / cognitive | E12: 7 | F12: 5 | G12: 4 hours | H12: New | I12: Head | J12: Afternoon | K12: Poor sleep; flare | L12: Dark room; fluids | M12: Resolved by evening | N12: Yes | O12: No | P12: No neurologic red flags in sample entry
A13: 46289 | B13: 08:00 | C13: Fatigue | D13: Constitutional | E13: 7 | F13: 7 | G13: Most of day | H13: Better | I13: Whole body | J13: On waking | K13: Recovery beginning | L13: Rest; pacing | M13: Gradually improved | N13: No | O13: No | P13: Lower than peak
A14: 46293 | B14: 12:00 | C14: Joint pain and stiffness | D14: Joint / muscle | E14: 5 | F14: 4 | G14: Intermittent | H14: Better | I14: Hands | J14: Midday | K14: Recovery | L14: Usual care | M14: Improved | N14: No | O14: No | P14: Approaching baseline
A15: 46298 | B15: 19:00 | C15: Bloating | D15: GI | E15: 4 | F15: 2 | G15: 3 hours | H15: New | I15: Abdomen | J15: After food reintroduction | K15: Food | L15: Observed only | M15: Resolved without action | N15: Yes | O15: No | P15: Possible reaction; not conclusive

Sheet Flare Log
A1: Flare Log
A3: Track distinct flare episodes using your own definition from Profile & Goals.
A5: Flare Start | B5: Flare End | C5: Duration (days) | D5: Peak Severity 0–10 | E5: Suspected Trigger / Context | F5: Main Symptoms / Systems | G5: Function Impact | H5: Work / School / Caregiving Impact | I5: Treatments / Actions | J5: Provider Contact / Care Sought | K5: Labs / Tests | L5: Outcome / Recovery | M5: Back to Baseline? | N5: Notes
A6: 46284 | B6: 46293 | C6: =IF(OR(A6="",B6=""),"",B6-A6+1) -> 10 | D6: 9 | E6: Sun exposure + poor sleep; treatment delay may also have contributed | F6: Fatigue, joint pain, rash, brain fog, mouth sore | G6: Reduced ability to complete usual tasks | H6: Missed one social commitment; shortened work blocks | I6: Pacing, rest, usual medications; provider message | J6: Message sent to rheumatology 9/21 | K6: CBC, CMP, inflammatory markers ordered | L6: Gradual improvement over ~10 days | M6: Yes | N6: Fictional example episode used to demonstrate cross-sheet tracking
C7: =IF(A7="","",IF(B7="",TODAY()-A7+1,B7-A7+1))
C8: =IF(A8="","",IF(B8="",TODAY()-A8+1,B8-A8+1))
C9: =IF(A9="","",IF(B9="",TODAY()-A9+1,B9-A9+1))
C10: =IF(A10="","",IF(B10="",TODAY()-A10+1,B10-A10+1))
C11: =IF(A11="","",IF(B11="",TODAY()-A11+1,B11-A11+1))
C12: =IF(A12="","",IF(B12="",TODAY()-A12+1,B12-A12+1))
C13: =IF(A13="","",IF(B13="",TODAY()-A13+1,B13-A13+1))
C14: =IF(A14="","",IF(B14="",TODAY()-A14+1,B14-A14+1))
C15: =IF(A15="","",IF(B15="",TODAY()-A15+1,B15-A15+1))
C16: =IF(A16="","",IF(B16="",TODAY()-A16+1,B16-A16+1))
C17: =IF(A17="","",IF(B17="",TODAY()-A17+1,B17-A17+1))
C18: =IF(A18="","",IF(B18="",TODAY()-A18+1,B18-A18+1))
... C155: =IF(A155="","",IF(B155="",TODAY()-A155+1,B155-A155+1))

Sheet Treatments
A1: Treatment Plan
A3: Track prescribed and non-prescribed interventions in one place, including treatments that are paused, stopped, planned, or currently difficult to access.
A5: Treatment / Intervention | B5: Type | C5: Status | D5: Goal / Indication | E5: Prescriber / Source | F5: Dose / Strength | G5: Route | H5: Frequency / Schedule | I5: Start Date | J5: Last Taken / Given | K5: Typical Interval (days) | L5: Next Expected | M5: End Date | N5: Reason Paused / Stopped / Not Started | O5: Access Barrier? | P5: Cost / Coverage Notes | Q5: Perceived Benefit 0–10 | R5: Side Effect / Burden 0–10 | S5: Notes
A6: Example maintenance medication | B6: Medication | C6: Active | D6: Baseline symptom control | E6: Rheumatology | F6: 200 mg | G6: Oral | H6: Daily | I6: 45992 | J6: 46302 | K6: 1 | L6: =IF(OR(J6="",K6=""),"",J6+K6) -> 46303 | O6: No | Q6: 6 | R6: 2 | S6: Fictional medication entry; name intentionally generic
A7: Example biologic infusion | B7: Infusion | C7: Active | D7: Reduce inflammatory disease activity | E7: Rheumatology | F7: Example dose | G7: IV | H7: Every 56 days | I7: 46054 | J7: 46290 | K7: 56 | L7: =IF(OR(J7="",K7=""),"",J7+K7) -> 46346 | O7: Yes | P7: Prior authorization delayed scheduled dose by several days | Q7: 8 | R7: 3 | S7: Fictional infusion used to demonstrate access + timing tracking
A8: Vitamin D | B8: Supplement | C8: Active | D8: Supplement per prior lab discussion | E8: Primary care | F8: 1000 IU | G8: Oral | H8: Daily | I8: 46082 | J8: 46302 | K8: 1 | L8: =IF(OR(J8="",K8=""),"",J8+K8) -> 46303 | O8: No | Q8: 4 | R8: 0 | S8: Sample supplement
A9: AIP-style elimination / reintroduction | B9: Nutrition / AIP | C9: Active | D9: Observe food tolerance patterns | E9: Self-directed | F9: N/A | G9: Food plan | H9: Daily | I9: 46275 | J9: 46302 | K9: 1 | L9: =IF(OR(J9="",K9=""),"",J9+K9) -> 46303 | O9: No | Q9: 5 | R9: 4 | S9: Demonstration only; tracks observations rather than proving causation
L10: =IF(AND(C10="Active",J10<>"",K10<>""),J10+K10,"")
L11: =IF(AND(C11="Active",J11<>"",K11<>""),J11+K11,"")
L12: =IF(AND(C12="Active",J12<>"",K12<>""),J12+K12,"")
L13: =IF(AND(C13="Active",J13<>"",K13<>""),J13+K13,"")
L14: =IF(AND(C14="Active",J14<>"",K14<>""),J14+K14,"")
L15: =IF(AND(C15="Active",J15<>"",K15<>""),J15+K15,"")
L16: =IF(AND(C16="Active",J16<>"",K16<>""),J16+K16,"")
L17: =IF(AND(C17="Active",J17<>"",K17<>""),J17+K17,"")
L18: =IF(AND(C18="Active",J18<>"",K18<>""),J18+K18,"")
L19: =IF(AND(C19="Active",J19<>"",K19<>""),J19+K19,"")
L20: =IF(AND(C20="Active",J20<>"",K20<>""),J20+K20,"")
L21: =IF(AND(C21="Active",J21<>"",K21<>""),J21+K21,"")
... L155: =IF(AND(C155="Active",J155<>"",K155<>""),J155+K155,"")

Sheet Treatment Events
A1: Treatment Events
A3: Record what actually happened: taken/given, missed, held, changed, delayed, started, or stopped. This makes timing, response, and side effects easier to compare.
A5: Date | B5: Time | C5: Treatment / Intervention | D5: Event Type | E5: Dose / Details | F5: Taken / Given as Planned? | G5: Reason if Missed / Held / Delayed | H5: Immediate Side Effects | I5: Side Effect Severity 0–10 | J5: 0–24h Response | K5: 24–72h Response | L5: Perceived Benefit 0–10 | M5: Access Issue? | N5: Notes
A6: 46275 | B6: 08:00 | C6: Example maintenance medication | D6: Taken / given | E6: Usual dose | F6: Yes | H6: None | I6: 0 | J6: No immediate change | K6: Baseline stable | L6: 6 | M6: No | N6: Routine dose
A7: 46286 | B7: 09:00 | C7: Example biologic infusion | D7: Delayed | E7: Scheduled infusion not given | F7: No | G7: Prior authorization pending | H7: N/A | I7: 0 | J7: Flare remained active | K7: Symptoms still elevated | L7: 0 | M7: Yes | N7: Expected infusion date; unable to receive treatment
A8: 46288 | B8: 15:00 | C8: Example biologic infusion | D8: Delayed | E8: Rescheduled | F8: No | G8: Authorization still pending | H8: N/A | I8: 0 | J8: No immediate change | K8: Symptoms slowly improving | L8: 0 | M8: Yes | N8: Second delay
A9: 46290 | B9: 11:00 | C9: Example biologic infusion | D9: Taken / given | E9: Infusion completed | F9: Yes | H9: Mild fatigue afterward | I9: 3 | J9: Rested after infusion | K9: Fatigue improved over next several days | L9: 8 | M9: No | N9: Authorization approved
A10: 46296 | B10: 08:00 | C10: Example maintenance medication | D10: Taken / given | E10: Usual dose | F10: Yes | H10: None | I10: 0 | J10: No immediate change | K10: Stable | L10: 6 | M10: No | N10: Routine
A11: 46302 | B11: 08:00 | C11: Vitamin D | D11: Taken / given | E11: 1000 IU | F11: Yes | H11: None | I11: 0 | J11: None | K11: None expected | L11: 4 | M11: No | N11: Routine

Sheet AIP & Nutrition
A1: AIP & Nutrition
A3: Use this to track AIP or another nutrition approach, including phases, meals, reintroductions, reactions, and changes over time.
A5: Date | B5: AIP Phase | C5: Entry Type | D5: Food / Ingredient / Meal | E5: Food Group | F5: Time | G5: Reintroduction Stage / Details | H5: New or Reintroduced? | I5: Symptoms Before 0–10 | J5: Peak Symptoms After 0–10 | K5: Time to Change | L5: Reaction / Change Type | M5: Result | N5: Decision / Next Step | O5: Notes
A6: 46275 | B6: Elimination | C6: Plan change | D6: Begin simplified elimination phase | E6: Overall plan | G6: Baseline period | H6: No | I6: 3 | J6: 3 | L6: Not a test | M6: Not a test | N6: Track baseline for 2+ weeks | O6: Started sample tracking period
A7: 46283 | B7: Elimination | C7: Meal / food | D7: Chicken, sweet potato, greens | E7: Mixed meal | F7: 12:30 | H7: No | I7: 5 | J7: 5 | L7: Not a test | M7: Not a test | N7: Continue | O7: No obvious food-related change
A8: 46289 | B8: Elimination | C8: Meal / food | D8: Salmon, squash, greens | E8: Mixed meal | F8: 18:00 | H8: No | I8: 7 | J8: 7 | L8: Not a test | M8: Not a test | N8: Continue | O8: Flare already improving
A9: 46297 | B9: Reintroduction | C9: Reintroduction test | D9: Egg yolk | E9: Egg | F9: 09:00 | G9: Small portion, day 1 | H9: Yes | I9: 3 | J9: 3 | K9: 24h | L9: Neutral / no clear change | M9: Tolerated | N9: Repeat per personal plan | O9: No obvious change
A10: 46298 | B10: Reintroduction | C10: Reintroduction test | D10: Whole egg | E10: Egg | F10: 09:00 | G10: Larger portion, day 2 | H10: Yes | I10: 3 | J10: 4 | K10: 10h | L10: GI symptoms | M10: Possible reaction | N10: Pause and observe | O10: Mild evening bloating
A11: 46299 | B11: Reintroduction | C11: Reaction / symptom note | D11: No egg | E11: Egg | G11: Observation day | H11: No | I11: 4 | J11: 3 | K11: 24h | L11: Improved | M11: Inconclusive | N11: Wait before deciding | O11: Symptoms resolved
A12: 46301 | B12: Personalized / maintenance | C12: Plan change | D12: Return to tolerated foods | E12: Overall plan | G12: After observation period | H12: No | I12: 3 | J12: 3 | L12: Not a test | M12: Not a test | N12: Document egg as uncertain for now | O12: Shows how a user can record an inconclusive result

Sheet Lifestyle & Triggers
A1: Lifestyle & Trigger Log
A3: Log notable exposures or protective factors—not every minute of every day. Think sleep loss, unusual stress, UV/sun, heat/cold, infection, activity, travel, allergens, hormonal changes, weather, pacing/rest, or anything else that might matter.
A5: Date | B5: Factor / Exposure | C5: Category | D5: Intensity / Amount 0–10 | E5: Duration / Timing | F5: Protective Action / What I Did | G5: Symptom Impact 0–10 | H5: Delay to Impact | I5: Helped / Worsened / Neutral | J5: Notes
A6: 46281 | B6: Short sleep | C6: Sleep | D6: 6 | E6: ~6 hours sleep | F6: Earlier bedtime next night | G6: 4 | H6: Next day | I6: Worsened | J6: Fatigue and brain fog increased
A7: 46282 | B7: High work stress | C7: Stress | D7: 7 | E7: Most of day | F7: Breaks and reduced evening plans | G7: 4 | H7: Same day | I7: Worsened | J7: Muscle tension and fatigue
A8: 46283 | B8: Outdoor sun exposure | C8: UV / sun | D8: 8 | E8: ~2 hours | F8: Hat, sunscreen, shade part of time | G8: 7 | H8: Hours | I8: Worsened | J8: Rash and fatigue rose that evening
A9: 46285 | B9: Extra rest / pacing | C9: Rest / pacing | D9: 8 | E9: Most of day | F9: Cancelled nonessential activity | G9: 5 | H9: Same day | I9: Helped | J9: Did not end flare but reduced overload
A10: 46287 | B10: Poor sleep | C10: Sleep | D10: 8 | E10: ~4 hours sleep | F10: Nap; low-stimulation evening | G10: 6 | H10: Same day | I10: Worsened | J10: Headache and fatigue higher
A11: 46291 | B11: Gentle walk | C11: Activity | D11: 3 | E11: 20 minutes | F11: Stopped before fatigue increased | G11: 2 | H11: Same day | I11: Helped | J11: Tolerated during recovery
A12: 46296 | B12: Consistent sleep | C12: Sleep | D12: 8 | E12: 7.5 hours | F12: Kept regular bedtime | G12: 3 | H12: Next day | I12: Helped | J12: Energy and function improved
A13: 46300 | B13: Cold morning | C13: Cold | D13: 5 | E13: ~1 hour | F13: Warm layers | G13: 2 | H13: During exposure | I13: Neutral / no clear change | J13: No sustained symptom change

Sheet Labs
A1: Labs
A3: Enter the reference range shown on the same lab report. Auto Flag compares numeric results with the low and high values you enter.
A5: Date | B5: Test | C5: Result | D5: Units | E5: Reference Low | F5: Reference High | G5: Auto Flag | H5: Ordering Provider | I5: Lab / Facility | J5: Related Flare / Context | K5: Notes
A6: 46287 | B6: WBC | C6: 3.7 | D6: x10^3/uL | E6: 4 | F6: 11 | G6: =IF(C6="","",IF(AND(ISNUMBER(E6),C6<E6),"Low",IF(AND(ISNUMBER(F6),C6>F6),"High","In range"))) -> Low | H6: Rheumatology | I6: Example Lab | J6: During flare | K6: Sample numeric lab to demonstrate auto flag
A7: 46287 | B7: Hemoglobin | C7: 12.4 | D7: g/dL | E7: 12 | F7: 15.5 | G7: =IF(C7="","",IF(AND(ISNUMBER(E7),C7<E7),"Low",IF(AND(ISNUMBER(F7),C7>F7),"High","In range"))) -> In range | H7: Rheumatology | I7: Example Lab | J7: During flare
A8: 46287 | B8: Platelets | C8: 210 | D8: x10^3/uL | E8: 150 | F8: 450 | G8: =IF(C8="","",IF(AND(ISNUMBER(E8),C8<E8),"Low",IF(AND(ISNUMBER(F8),C8>F8),"High","In range"))) -> In range | H8: Rheumatology | I8: Example Lab | J8: During flare
A9: 46287 | B9: Creatinine | C9: 0.8 | D9: mg/dL | E9: 0.6 | F9: 1.1 | G9: =IF(C9="","",IF(AND(ISNUMBER(E9),C9<E9),"Low",IF(AND(ISNUMBER(F9),C9>F9),"High","In range"))) -> In range | H9: Rheumatology | I9: Example Lab | J9: During flare
A10: 46287 | B10: ALT | C10: 24 | D10: U/L | E10: 7 | F10: 35 | G10: =IF(C10="","",IF(AND(ISNUMBER(E10),C10<E10),"Low",IF(AND(ISNUMBER(F10),C10>F10),"High","In range"))) -> In range | H10: Rheumatology | I10: Example Lab | J10: During flare
A11: 46287 | B11: CRP | C11: 1.6 | D11: mg/dL | E11: 0 | F11: 0.8 | G11: =IF(C11="","",IF(AND(ISNUMBER(E11),C11<E11),"Low",IF(AND(ISNUMBER(F11),C11>F11),"High","In range"))) -> High | H11: Rheumatology | I11: Example Lab | J11: During flare | K11: Sample elevated result
A12: 46301 | B12: WBC | C12: 4.4 | D12: x10^3/uL | E12: 4 | F12: 11 | G12: =IF(C12="","",IF(AND(ISNUMBER(E12),C12<E12),"Low",IF(AND(ISNUMBER(F12),C12>F12),"High","In range"))) -> In range | H12: Rheumatology | I12: Example Lab | J12: Recovery / near baseline | K12: Repeat sample result
A13: 46301 | B13: CRP | C13: 0.6 | D13: mg/dL | E13: 0 | F13: 0.8 | G13: =IF(C13="","",IF(AND(ISNUMBER(E13),C13<E13),"Low",IF(AND(ISNUMBER(F13),C13>F13),"High","In range"))) -> In range | H13: Rheumatology | I13: Example Lab | J13: Recovery / near baseline | K13: Repeat sample result
G14: =IF(C14="","",IF(NOT(ISNUMBER(C14)),"See lab report",IF(AND(ISNUMBER(E14),C14<E14),"Low",IF(AND(ISNUMBER(F14),C14>F14),"High",IF(OR(ISNUMBER(E14),ISNUMBER(F14)),"In range","See lab report")))))
G15: =IF(C15="","",IF(NOT(ISNUMBER(C15)),"See lab report",IF(AND(ISNUMBER(E15),C15<E15),"Low",IF(AND(ISNUMBER(F15),C15>F15),"High",IF(OR(ISNUMBER(E15),ISNUMBER(F15)),"In range","See lab report")))))
G16: =IF(C16="","",IF(NOT(ISNUMBER(C16)),"See lab report",IF(AND(ISNUMBER(E16),C16<E16),"Low",IF(AND(ISNUMBER(F16),C16>F16),"High",IF(OR(ISNUMBER(E16),ISNUMBER(F16)),"In range","See lab report")))))
G17: =IF(C17="","",IF(NOT(ISNUMBER(C17)),"See lab report",IF(AND(ISNUMBER(E17),C17<E17),"Low",IF(AND(ISNUMBER(F17),C17>F17),"High",IF(OR(ISNUMBER(E17),ISNUMBER(F17)),"In range","See lab report")))))
G18: =IF(C18="","",IF(NOT(ISNUMBER(C18)),"See lab report",IF(AND(ISNUMBER(E18),C18<E18),"Low",IF(AND(ISNUMBER(F18),C18>F18),"High",IF(OR(ISNUMBER(E18),ISNUMBER(F18)),"In range","See lab report")))))
G19: =IF(C19="","",IF(NOT(ISNUMBER(C19)),"See lab report",IF(AND(ISNUMBER(E19),C19<E19),"Low",IF(AND(ISNUMBER(F19),C19>F19),"High",IF(OR(ISNUMBER(E19),ISNUMBER(F19)),"In range","See lab report")))))
G20: =IF(C20="","",IF(NOT(ISNUMBER(C20)),"See lab report",IF(AND(ISNUMBER(E20),C20<E20),"Low",IF(AND(ISNUMBER(F20),C20>F20),"High",IF(OR(ISNUMBER(E20),ISNUMBER(F20)),"In range","See lab report")))))
G21: =IF(C21="","",IF(NOT(ISNUMBER(C21)),"See lab report",IF(AND(ISNUMBER(E21),C21<E21),"Low",IF(AND(ISNUMBER(F21),C21>F21),"High",IF(OR(ISNUMBER(E21),ISNUMBER(F21)),"In range","See lab report")))))
G22: =IF(C22="","",IF(NOT(ISNUMBER(C22)),"See lab report",IF(AND(ISNUMBER(E22),C22<E22),"Low",IF(AND(ISNUMBER(F22),C22>F22),"High",IF(OR(ISNUMBER(E22),ISNUMBER(F22)),"In range","See lab report")))))
G23: =IF(C23="","",IF(NOT(ISNUMBER(C23)),"See lab report",IF(AND(ISNUMBER(E23),C23<E23),"Low",IF(AND(ISNUMBER(F23),C23>F23),"High",IF(OR(ISNUMBER(E23),ISNUMBER(F23)),"In range","See lab report")))))
G24: =IF(C24="","",IF(NOT(ISNUMBER(C24)),"See lab report",IF(AND(ISNUMBER(E24),C24<E24),"Low",IF(AND(ISNUMBER(F24),C24>F24),"High",IF(OR(ISNUMBER(E24),ISNUMBER(F24)),"In range","See lab report")))))
G25: =IF(C25="","",IF(NOT(ISNUMBER(C25)),"See lab report",IF(AND(ISNUMBER(E25),C25<E25),"Low",IF(AND(ISNUMBER(F25),C25>F25),"High",IF(OR(ISNUMBER(E25),ISNUMBER(F25)),"In range","See lab report")))))
... G255: =IF(C255="","",IF(NOT(ISNUMBER(C255)),"See lab report",IF(AND(ISNUMBER(E255),C255<E255),"Low",IF(AND(ISNUMBER(F255),C255>F255),"High",IF(OR(ISNUMBER(E255),ISNUMBER(F255)),"In range","See lab report")))))

Sheet Appointments
A1: Appointments & Provider Conversations
A3: Use before and after a visit. Bring questions and patterns in; capture decisions and next steps on the way out.
A5: Date | B5: Provider | C5: Specialty | D5: Visit Type | E5: Main Goal | F5: Questions I Want Answered | G5: Key Symptoms / Changes to Discuss | H5: Data / Records to Bring | I5: Decisions / Assessment | J5: Tests / Labs Ordered | K5: Referrals | L5: Treatment Changes | M5: Follow-Up / Next Step | N5: Next Appointment
A6: 46286 | B6: Rheumatology nurse | C6: Rheumatology | D6: Telehealth | E6: Report flare and treatment delay | F6: Should any labs be checked? What should I do if authorization is still pending? | G6: Fatigue, joint pain, rash, brain fog; infusion delayed | H6: Daily log; symptom entries; medication list | I6: Labs ordered; office to follow up on authorization | J6: CBC, CMP, CRP | L6: No change until physician review | M6: Complete labs; call if symptoms worsen | N6: 46303
A7: 46290 | B7: Infusion center | C7: Infusion therapy | D7: Procedure / infusion | E7: Receive delayed infusion | F7: Confirm authorization and next expected date | G7: Current flare improving but not resolved | H7: Authorization approval; medication list | I7: Infusion completed | L7: Infusion given | M7: Track response over 72 hours | N7: 46346
A8: 46303 | B8: Rheumatologist | C8: Rheumatology | D8: Follow-up | E8: Review flare pattern and recovery | F8: Did timing suggest any treatment wear-off? Any tests or plan changes? | G8: Trend chart; high-severity events; flare log; labs; access delay | H8: Dashboard; labs; flare log; care access notes | I8: Sample future visit — no outcome entered yet | M8: Bring tracker summary

Sheet Care Access
A1: Care Access & Insurance Barriers
A3: Document barriers that change your ability to receive care: prior authorization, denial, loss of coverage, cost, referral delays, waitlists, scheduling, transportation, pharmacy supply, or anything else.
A5: Date | B5: Item / Service | C5: Type | D5: Status | E5: Payer / Program / Provider | F5: Barrier / Reason Given | G5: Reference / Case / Authorization # | H5: Cost Quote / Patient Cost | I5: Action Taken | J5: Person / Office Contacted | K5: Next Step | L5: Next Follow-Up Date | M5: Outcome | N5: Notes
A6: 46283 | B6: Example biologic infusion | C6: Infusion / injection | D6: Prior authorization pending | E6: Example Health Plan | F6: Renewal authorization required | G6: PA-EXAMPLE-001 | H6: $0 if approved; high self-pay cost | I6: Clinic submitted authorization | J6: Rheumatology authorization team | K6: Wait for payer response | L6: 46286 | N6: Sample only — demonstrates how access timing can be tracked
A7: 46286 | B7: Example biologic infusion | C7: Infusion / injection | D7: Prior authorization pending | E7: Example Health Plan | F7: Additional records requested | G7: PA-EXAMPLE-001 | I7: Clinic sent requested records | J7: Rheumatology authorization team | K7: Check status | L7: 46288 | N7: Scheduled dose delayed
A8: 46288 | B8: Example biologic infusion | C8: Infusion / injection | D8: Approved | E8: Example Health Plan | F8: Authorization completed | G8: PA-EXAMPLE-001 | H8: $0 | I8: Infusion rescheduled | J8: Infusion center | K8: Attend rescheduled infusion | L8: 46290 | M8: Approved | N8: Access issue resolved
A9: 46300 | B9: Rheumatology follow-up | C9: Specialist | D9: Scheduling | E9: Rheumatology clinic | F9: Next routine slot unavailable for several weeks | I9: Asked for cancellation list | J9: Scheduling office | K9: Watch for earlier opening | L9: 46307 | N9: Open scheduling issue included so dashboard shows a pending access item

Sheet Diagnostic Journey
A1: Diagnostic Journey
A3: Use this when symptoms span time or multiple specialists. Record what was considered, what information was reviewed, conclusions, and next steps.
A5: Date | B5: Condition / Clinical Question | C5: Status | D5: Provider / Specialty | E5: Reason Discussed / Evidence | F5: Tests / Criteria / Records Reviewed | G5: Next Step | H5: Notes
A6: 45601 | B6: Systemic autoimmune / inflammatory condition | C6: Suspected / under evaluation | D6: Primary care | E6: Fatigue, joint pain, intermittent rash across several months | F6: Initial labs; symptom history | G6: Refer to rheumatology | H6: Historical sample entry
A7: 45700 | B7: Systemic autoimmune / inflammatory condition | C7: Diagnosed / confirmed | D7: Rheumatology | E7: Persistent multi-system symptoms plus clinical/lab assessment | F7: Specialist evaluation and prior records | G7: Begin treatment plan and monitoring | H7: Fictional example; not intended as diagnostic criteria
A8: 46286 | B8: Current flare: infection vs disease activity | C8: Patient question to raise | D8: Rheumatology | E8: Sudden symptom increase after sun exposure and poor sleep | F8: Symptoms, temperature, exposure history; labs ordered | G8: Review lab results and symptom course | H8: Shows how a clinical question can be tracked without self-diagnosing
A9: 46303 | B9: Treatment timing / breakthrough symptoms | C9: Monitoring | D9: Rheumatology | E9: Flare occurred near delayed infusion | F9: Dashboard trend, treatment events, care access timeline | G9: Discuss whether timing is meaningful | H9: Future sample appointment question

Sheet Dashboard
A1: 30-Day Review Dashboard
A3: Change the dates below to review any time window. Dashboard cards and the trend chart update automatically as you add entries.
A5: Review window | J5: Date | K5: Overall Burden | L5: Pain | M5: Fatigue
A6: Start Date | B6: 46273 | C6: End Date | D6: 46302 | J6: =IF('Daily Check-In'!A6="","",'Daily Check-In'!A6) -> 46275 | K6: =IF(OR('Daily Check-In'!A6="",'Daily Check-In'!C6=""),"",'Daily Check-In'!C6) -> 3 | L6: =IF(OR('Daily Check-In'!A6="",'Daily Check-In'!D6=""),"",'Daily Check-In'!D6) -> 2 | M6: =IF(OR('Daily Check-In'!A6="",'Daily Check-In'!E6=""),"",'Daily Check-In'!E6) -> 4
A7: DEMO VIEW: dates are fixed to the fictional sample period. Change Start Date or End Date to test another window. | J7: =IF('Daily Check-In'!A7="","",'Daily Check-In'!A7) -> 46276 | K7: =IF(OR('Daily Check-In'!A7="",'Daily Check-In'!C7=""),"",'Daily Check-In'!C7) -> 3 | L7: =IF(OR('Daily Check-In'!A7="",'Daily Check-In'!D7=""),"",'Daily Check-In'!D7) -> 2 | M7: =IF(OR('Daily Check-In'!A7="",'Daily Check-In'!E7=""),"",'Daily Check-In'!E7) -> 4
J8: =IF('Daily Check-In'!A8="","",'Daily Check-In'!A8) -> 46277 | K8: =IF(OR('Daily Check-In'!A8="",'Daily Check-In'!C8=""),"",'Daily Check-In'!C8) -> 4 | L8: =IF(OR('Daily Check-In'!A8="",'Daily Check-In'!D8=""),"",'Daily Check-In'!D8) -> 3 | M8: =IF(OR('Daily Check-In'!A8="",'Daily Check-In'!E8=""),"",'Daily Check-In'!E8) -> 5
A9: Snapshot | J9: =IF('Daily Check-In'!A9="","",'Daily Check-In'!A9) -> 46278 | K9: =IF(OR('Daily Check-In'!A9="",'Daily Check-In'!C9=""),"",'Daily Check-In'!C9) -> 3 | L9: =IF(OR('Daily Check-In'!A9="",'Daily Check-In'!D9=""),"",'Daily Check-In'!D9) -> 2 | M9: =IF(OR('Daily Check-In'!A9="",'Daily Check-In'!E9=""),"",'Daily Check-In'!E9) -> 4
A10: Days Logged | C10: Flare Days | E10: Avg Symptom Burden | G10: High-Severity Symptom Entries | J10: =IF('Daily Check-In'!A10="","",'Daily Check-In'!A10) -> 46279 | K10: =IF(OR('Daily Check-In'!A10="",'Daily Check-In'!C10=""),"",'Daily Check-In'!C10) -> 3 | L10: =IF(OR('Daily Check-In'!A10="",'Daily Check-In'!D10=""),"",'Daily Check-In'!D10) -> 2 | M10: =IF(OR('Daily Check-In'!A10="",'Daily Check-In'!E10=""),"",'Daily Check-In'!E10) -> 4
A11: =IF(COUNTIFS('Daily Check-In'!$A$6:$A$370,">="&$B$6,'Daily Check-In'!$A$6:$A$370,"<="&$D$6)=0,"No data yet",COUNTIFS('Daily Check-In'!$A$6:$A$370,">="&$B$6,'Daily Check-In'!$A$6:$A$370,"<="&$D$6)) -> 28 | C11: =IF(COUNTIFS('Daily Check-In'!$A$6:$A$370,">="&$B$6,'Daily Check-In'!$A$6:$A$370,"<="&$D$6)=0,"No data yet",COUNTIFS('Daily Check-In'!$A$6:$A$370,">="&$B$6,'Daily Check-In'!$A$6:$A$370,"<="&$D$6,'Daily Check-In'!$B$6:$B$370,"Flare")) -> 6 | E11: =IF(COUNTIFS('Daily Check-In'!$A$6:$A$370,">="&$B$6,'Daily Check-In'!$A$6:$A$370,"<="&$D$6,'Daily Check-In'!$C$6:$C$370,"<>")=0,"No data yet",SUMIFS('Daily Check-In'!$C$6:$C$370,'Daily Check-In'!$A$6:$A$370,">="&$B$6,'Daily Check-In'!$A$6:$A$370,"<="&$D$6)/COUNTIFS('Daily Check-In'!$A$6:$A$370,">="&$B$6,'Daily Check-In'!$A$6:$A$370,"<="&$D$6,'Daily Check-In'!$C$6:$C$370,"<>")) -> 4.7857143 | G11: =IF(COUNTIFS('Symptom Log'!$A$6:$A$255,">="&$B$6,'Symptom Log'!$A$6:$A$255,"<="&$D$6)=0,"No data yet",COUNTIFS('Symptom Log'!$A$6:$A$255,">="&$B$6,'Symptom Log'!$A$6:$A$255,"<="&$D$6,'Symptom Log'!$E$6:$E$255,">=7")) -> 7 | J11: =IF('Daily Check-In'!A11="","",'Daily Check-In'!A11) -> 46280 | K11: =IF(OR('Daily Check-In'!A11="",'Daily Check-In'!C11=""),"",'Daily Check-In'!C11) -> 4 | L11: =IF(OR('Daily Check-In'!A11="",'Daily Check-In'!D11=""),"",'Daily Check-In'!D11) -> 3 | M11: =IF(OR('Daily Check-In'!A11="",'Daily Check-In'!E11=""),"",'Daily Check-In'!E11) -> 5
J12: =IF('Daily Check-In'!A12="","",'Daily Check-In'!A12) -> 46281 | K12: =IF(OR('Daily Check-In'!A12="",'Daily Check-In'!C12=""),"",'Daily Check-In'!C12) -> 4 | L12: =IF(OR('Daily Check-In'!A12="",'Daily Check-In'!D12=""),"",'Daily Check-In'!D12) -> 3 | M12: =IF(OR('Daily Check-In'!A12="",'Daily Check-In'!E12=""),"",'Daily Check-In'!E12) -> 5
A13: Avg Pain | C13: Avg Fatigue | E13: Avg Energy | G13: Avg Function | J13: =IF('Daily Check-In'!A13="","",'Daily Check-In'!A13) -> 46282 | K13: =IF(OR('Daily Check-In'!A13="",'Daily Check-In'!C13=""),"",'Daily Check-In'!C13) -> 5 | L13: =IF(OR('Daily Check-In'!A13="",'Daily Check-In'!D13=""),"",'Daily Check-In'!D13) -> 4 | M13: =IF(OR('Daily Check-In'!A13="",'Daily Check-In'!E13=""),"",'Daily Check-In'!E13) -> 6
A14: =IF(COUNTIFS('Daily Check-In'!$A$6:$A$370,">="&$B$6,'Daily Check-In'!$A$6:$A$370,"<="&$D$6,'Daily Check-In'!$D$6:$D$370,"<>")=0,"No data yet",SUMIFS('Daily Check-In'!$D$6:$D$370,'Daily Check-In'!$A$6:$A$370,">="&$B$6,'Daily Check-In'!$A$6:$A$370,"<="&$D$6)/COUNTIFS('Daily Check-In'!$A$6:$A$370,">="&$B$6,'Daily Check-In'!$A$6:$A$370,"<="&$D$6,'Daily Check-In'!$D$6:$D$370,"<>")) -> 3.8214286 | C14: =IF(COUNTIFS('Daily Check-In'!$A$6:$A$370,">="&$B$6,'Daily Check-In'!$A$6:$A$370,"<="&$D$6,'Daily Check-In'!$E$6:$E$370,"<>")=0,"No data yet",SUMIFS('Daily Check-In'!$E$6:$E$370,'Daily Check-In'!$A$6:$A$370,">="&$B$6,'Daily Check-In'!$A$6:$A$370,"<="&$D$6)/COUNTIFS('Daily Check-In'!$A$6:$A$370,">="&$B$6,'Daily Check-In'!$A$6:$A$370,"<="&$D$6,'Daily Check-In'!$E$6:$E$370,"<>")) -> 5.4285714 | E14: =IF(COUNTIFS('Daily Check-In'!$A$6:$A$370,">="&$B$6,'Daily Check-In'!$A$6:$A$370,"<="&$D$6,'Daily Check-In'!$F$6:$F$370,"<>")=0,"No data yet",SUMIFS('Daily Check-In'!$F$6:$F$370,'Daily Check-In'!$A$6:$A$370,">="&$B$6,'Daily Check-In'!$A$6:$A$370,"<="&$D$6)/COUNTIFS('Daily Check-In'!$A$6:$A$370,">="&$B$6,'Daily Check-In'!$A$6:$A$370,"<="&$D$6,'Daily Check-In'!$F$6:$F$370,"<>")) -> 4.8571429 | G14: =IF(COUNTIFS('Daily Check-In'!$A$6:$A$370,">="&$B$6,'Daily Check-In'!$A$6:$A$370,"<="&$D$6,'Daily Check-In'!$J$6:$J$370,"<>")=0,"No data yet",SUMIFS('Daily Check-In'!$J$6:$J$370,'Daily Check-In'!$A$6:$A$370,">="&$B$6,'Daily Check-In'!$A$6:$A$370,"<="&$D$6)/COUNTIFS('Daily Check-In'!$A$6:$A$370,">="&$B$6,'Daily Check-In'!$A$6:$A$370,"<="&$D$6,'Daily Check-In'!$J$6:$J$370,"<>")) -> 6.6428571 | J14: =IF('Daily Check-In'!A14="","",'Daily Check-In'!A14) -> 46283 | K14: =IF(OR('Daily Check-In'!A14="",'Daily Check-In'!C14=""),"",'Daily Check-In'!C14) -> 6 | L14: =IF(OR('Daily Check-In'!A14="",'Daily Check-In'!D14=""),"",'Daily Check-In'!D14) -> 5 | M14: =IF(OR('Daily Check-In'!A14="",'Daily Check-In'!E14=""),"",'Daily Check-In'!E14) -> 7
J15: =IF('Daily Check-In'!A15="","",'Daily Check-In'!A15) -> 46284 | K15: =IF(OR('Daily Check-In'!A15="",'Daily Check-In'!C15=""),"",'Daily Check-In'!C15) -> 8 | L15: =IF(OR('Daily Check-In'!A15="",'Daily Check-In'!D15=""),"",'Daily Check-In'!D15) -> 7 | M15: =IF(OR('Daily Check-In'!A15="",'Daily Check-In'!E15=""),"",'Daily Check-In'!E15) -> 8
A16: Flare Episodes Started | C16: Treatment Events | E16: Open/Pending Access Issues | G16: Lab Results Logged | J16: =IF('Daily Check-In'!A16="","",'Daily Check-In'!A16) -> 46285 | K16: =IF(OR('Daily Check-In'!A16="",'Daily Check-In'!C16=""),"",'Daily Check-In'!C16) -> 8 | L16: =IF(OR('Daily Check-In'!A16="",'Daily Check-In'!D16=""),"",'Daily Check-In'!D16) -> 8 | M16: =IF(OR('Daily Check-In'!A16="",'Daily Check-In'!E16=""),"",'Daily Check-In'!E16) -> 9
A17: =IF(COUNTIFS('Flare Log'!$A$6:$A$155,">="&$B$6,'Flare Log'!$A$6:$A$155,"<="&$D$6)=0,"No data yet",COUNTIFS('Flare Log'!$A$6:$A$155,">="&$B$6,'Flare Log'!$A$6:$A$155,"<="&$D$6)) -> 1 | C17: =IF(COUNTIFS('Treatment Events'!$A$6:$A$255,">="&$B$6,'Treatment Events'!$A$6:$A$255,"<="&$D$6)=0,"No data yet",COUNTIFS('Treatment Events'!$A$6:$A$255,">="&$B$6,'Treatment Events'!$A$6:$A$255,"<="&$D$6)) -> 6 | E17: =IF(COUNTIFS('Care Access'!$A$6:$A$205,">="&$B$6,'Care Access'!$A$6:$A$205,"<="&$D$6)=0,"No data yet",COUNTIFS('Care Access'!$A$6:$A$205,">="&$B$6,'Care Access'!$A$6:$A$205,"<="&$D$6,'Care Access'!$D$6:$D$205,"<>Completed / resolved",'Care Access'!$D$6:$D$205,"<>Approved",'Care Access'!$D$6:$D$205,"<>")) -> 3 | G17: =IF(COUNTIFS(Labs!$A$6:$A$255,">="&$B$6,Labs!$A$6:$A$255,"<="&$D$6)=0,"No data yet",COUNTIFS(Labs!$A$6:$A$255,">="&$B$6,Labs!$A$6:$A$255,"<="&$D$6)) -> 8 | J17: =IF('Daily Check-In'!A17="","",'Daily Check-In'!A17) -> 46286 | K17: =IF(OR('Daily Check-In'!A17="",'Daily Check-In'!C17=""),"",'Daily Check-In'!C17) -> 9 | L17: =IF(OR('Daily Check-In'!A17="",'Daily Check-In'!D17=""),"",'Daily Check-In'!D17) -> 8 | M17: =IF(OR('Daily Check-In'!A17="",'Daily Check-In'!E17=""),"",'Daily Check-In'!E17) -> 9
J18: =IF('Daily Check-In'!A18="","",'Daily Check-In'!A18) -> 46287 | K18: =IF(OR('Daily Check-In'!A18="",'Daily Check-In'!C18=""),"",'Daily Check-In'!C18) -> 8 | L18: =IF(OR('Daily Check-In'!A18="",'Daily Check-In'!D18=""),"",'Daily Check-In'!D18) -> 7 | M18: =IF(OR('Daily Check-In'!A18="",'Daily Check-In'!E18=""),"",'Daily Check-In'!E18) -> 8
J19: =IF('Daily Check-In'!A19="","",'Daily Check-In'!A19) -> 46288 | K19: =IF(OR('Daily Check-In'!A19="",'Daily Check-In'!C19=""),"",'Daily Check-In'!C19) -> 7 | L19: =IF(OR('Daily Check-In'!A19="",'Daily Check-In'!D19=""),"",'Daily Check-In'!D19) -> 6 | M19: =IF(OR('Daily Check-In'!A19="",'Daily Check-In'!E19=""),"",'Daily Check-In'!E19) -> 8
A20: Questions to ask when reviewing your data | J20: =IF('Daily Check-In'!A20="","",'Daily Check-In'!A20) -> 46289 | K20: =IF(OR('Daily Check-In'!A20="",'Daily Check-In'!C20=""),"",'Daily Check-In'!C20) -> 7 | L20: =IF(OR('Daily Check-In'!A20="",'Daily Check-In'!D20=""),"",'Daily Check-In'!D20) -> 6 | M20: =IF(OR('Daily Check-In'!A20="",'Daily Check-In'!E20=""),"",'Daily Check-In'!E20) -> 7
A21: • What changed before the flare or improvement—treatment timing, infection, sleep, stress, UV/temperature, activity, hormones, food, or access to care? | J21: =IF('Daily Check-In'!A21="","",'Daily Check-In'!A21) -> 46290 | K21: =IF(OR('Daily Check-In'!A21="",'Daily Check-In'!C21=""),"",'Daily Check-In'!C21) -> 6 | L21: =IF(OR('Daily Check-In'!A21="",'Daily Check-In'!D21=""),"",'Daily Check-In'!D21) -> 5 | M21: =IF(OR('Daily Check-In'!A21="",'Daily Check-In'!E21=""),"",'Daily Check-In'!E21) -> 7
A22: • Are symptoms repeatedly affecting the same body systems, or are new systems appearing? | J22: =IF('Daily Check-In'!A22="","",'Daily Check-In'!A22) -> 46291 | K22: =IF(OR('Daily Check-In'!A22="",'Daily Check-In'!C22=""),"",'Daily Check-In'!C22) -> 6 | L22: =IF(OR('Daily Check-In'!A22="",'Daily Check-In'!D22=""),"",'Daily Check-In'!D22) -> 5 | M22: =IF(OR('Daily Check-In'!A22="",'Daily Check-In'!E22=""),"",'Daily Check-In'!E22) -> 6
A23: • Does a treatment appear to help, wear off, create side effects, or become unavailable at a consistent time? | J23: =IF('Daily Check-In'!A23="","",'Daily Check-In'!A23) -> 46292 | K23: =IF(OR('Daily Check-In'!A23="",'Daily Check-In'!C23=""),"",'Daily Check-In'!C23) -> 5 | L23: =IF(OR('Daily Check-In'!A23="",'Daily Check-In'!D23=""),"",'Daily Check-In'!D23) -> 4 | M23: =IF(OR('Daily Check-In'!A23="",'Daily Check-In'!E23=""),"",'Daily Check-In'!E23) -> 6
A24: • What deserves a provider conversation, objective testing, treatment discussion, or access follow-up? | J24: =IF('Daily Check-In'!A24="","",'Daily Check-In'!A24) -> 46293 | K24: =IF(OR('Daily Check-In'!A24="",'Daily Check-In'!C24=""),"",'Daily Check-In'!C24) -> 5 | L24: =IF(OR('Daily Check-In'!A24="",'Daily Check-In'!D24=""),"",'Daily Check-In'!D24) -> 4 | M24: =IF(OR('Daily Check-In'!A24="",'Daily Check-In'!E24=""),"",'Daily Check-In'!E24) -> 5
J25: =IF('Daily Check-In'!A25="","",'Daily Check-In'!A25) -> 46294 | K25: =IF(OR('Daily Check-In'!A25="",'Daily Check-In'!C25=""),"",'Daily Check-In'!C25) -> 4 | L25: =IF(OR('Daily Check-In'!A25="",'Daily Check-In'!D25=""),"",'Daily Check-In'!D25) -> 3 | M25: =IF(OR('Daily Check-In'!A25="",'Daily Check-In'!E25=""),"",'Daily Check-In'!E25) -> 5
J26: =IF('Daily Check-In'!A26="","",'Daily Check-In'!A26) -> 46295 | K26: =IF(OR('Daily Check-In'!A26="",'Daily Check-In'!C26=""),"",'Daily Check-In'!C26) -> 4 | L26: =IF(OR('Daily Check-In'!A26="",'Daily Check-In'!D26=""),"",'Daily Check-In'!D26) -> 3 | M26: =IF(OR('Daily Check-In'!A26="",'Daily Check-In'!E26=""),"",'Daily Check-In'!E26) -> 4
J27: =IF('Daily Check-In'!A27="","",'Daily Check-In'!A27) -> 46296 | K27: =IF(OR('Daily Check-In'!A27="",'Daily Check-In'!C27=""),"",'Daily Check-In'!C27) -> 3 | L27: =IF(OR('Daily Check-In'!A27="",'Daily Check-In'!D27=""),"",'Daily Check-In'!D27) -> 2 | M27: =IF(OR('Daily Check-In'!A27="",'Daily Check-In'!E27=""),"",'Daily Check-In'!E27) -> 4
J28: =IF('Daily Check-In'!A28="","",'Daily Check-In'!A28) -> 46297 | K28: =IF(OR('Daily Check-In'!A28="",'Daily Check-In'!C28=""),"",'Daily Check-In'!C28) -> 3 | L28: =IF(OR('Daily Check-In'!A28="",'Daily Check-In'!D28=""),"",'Daily Check-In'!D28) -> 2 | M28: =IF(OR('Daily Check-In'!A28="",'Daily Check-In'!E28=""),"",'Daily Check-In'!E28) -> 4
J29: =IF('Daily Check-In'!A29="","",'Daily Check-In'!A29) -> 46298 | K29: =IF(OR('Daily Check-In'!A29="",'Daily Check-In'!C29=""),"",'Daily Check-In'!C29) -> 4 | L29: =IF(OR('Daily Check-In'!A29="",'Daily Check-In'!D29=""),"",'Daily Check-In'!D29) -> 3 | M29: =IF(OR('Daily Check-In'!A29="",'Daily Check-In'!E29=""),"",'Daily Check-In'!E29) -> 4
J30: =IF('Daily Check-In'!A30="","",'Daily Check-In'!A30) -> 46299 | K30: =IF(OR('Daily Check-In'!A30="",'Daily Check-In'!C30=""),"",'Daily Check-In'!C30) -> 3 | L30: =IF(OR('Daily Check-In'!A30="",'Daily Check-In'!D30=""),"",'Daily Check-In'!D30) -> 2 | M30: =IF(OR('Daily Check-In'!A30="",'Daily Check-In'!E30=""),"",'Daily Check-In'!E30) -> 4
J31: =IF('Daily Check-In'!A31="","",'Daily Check-In'!A31) -> 46300 | K31: =IF(OR('Daily Check-In'!A31="",'Daily Check-In'!C31=""),"",'Daily Check-In'!C31) -> 3 | L31: =IF(OR('Daily Check-In'!A31="",'Daily Check-In'!D31=""),"",'Daily Check-In'!D31) -> 2 | M31: =IF(OR('Daily Check-In'!A31="",'Daily Check-In'!E31=""),"",'Daily Check-In'!E31) -> 3
J32: =IF('Daily Check-In'!A32="","",'Daily Check-In'!A32) -> 46301 | K32: =IF(OR('Daily Check-In'!A32="",'Daily Check-In'!C32=""),"",'Daily Check-In'!C32) -> 3 | L32: =IF(OR('Daily Check-In'!A32="",'Daily Check-In'!D32=""),"",'Daily Check-In'!D32) -> 2 | M32: =IF(OR('Daily Check-In'!A32="",'Daily Check-In'!E32=""),"",'Daily Check-In'!E32) -> 3
J33: =IF('Daily Check-In'!A33="","",'Daily Check-In'!A33) -> 46302 | K33: =IF(OR('Daily Check-In'!A33="",'Daily Check-In'!C33=""),"",'Daily Check-In'!C33) -> 3 | L33: =IF(OR('Daily Check-In'!A33="",'Daily Check-In'!D33=""),"",'Daily Check-In'!D33) -> 2 | M33: =IF(OR('Daily Check-In'!A33="",'Daily Check-In'!E33=""),"",'Daily Check-In'!E33) -> 4
J34: =IF('Daily Check-In'!A34="","",'Daily Check-In'!A34) | K34: =IF(OR('Daily Check-In'!A34="",'Daily Check-In'!C34=""),"",'Daily Check-In'!C34) | L34: =IF(OR('Daily Check-In'!A34="",'Daily Check-In'!D34=""),"",'Daily Check-In'!D34) | M34: =IF(OR('Daily Check-In'!A34="",'Daily Check-In'!E34=""),"",'Daily Check-In'!E34)
J35: =IF('Daily Check-In'!A35="","",'Daily Check-In'!A35) | K35: =IF(OR('Daily Check-In'!A35="",'Daily Check-In'!C35=""),"",'Daily Check-In'!C35) | L35: =IF(OR('Daily Check-In'!A35="",'Daily Check-In'!D35=""),"",'Daily Check-In'!D35) | M35: =IF(OR('Daily Check-In'!A35="",'Daily Check-In'!E35=""),"",'Daily Check-In'!E35)
J36: =IF('Daily Check-In'!A36="","",'Daily Check-In'!A36) | K36: =IF(OR('Daily Check-In'!A36="",'Daily Check-In'!C36=""),"",'Daily Check-In'!C36) | L36: =IF(OR('Daily Check-In'!A36="",'Daily Check-In'!D36=""),"",'Daily Check-In'!D36) | M36: =IF(OR('Daily Check-In'!A36="",'Daily Check-In'!E36=""),"",'Daily Check-In'!E36)
... J370: =IF('Daily Check-In'!A370="","",'Daily Check-In'!A370) | K370: =IF(OR('Daily Check-In'!A370="",'Daily Check-In'!C370=""),"",'Daily Check-In'!C370) | L370: =IF(OR('Daily Check-In'!A370="",'Daily Check-In'!D370=""),"",'Daily Check-In'!D370) | M370: =IF(OR('Daily Check-In'!A370="",'Daily Check-In'!E370=""),"",'Daily Check-In'!E370)

Sheet Customize Lists
A1: Customize Dropdown Lists
A3: Each dropdown has its own list table below. Type over a choice to rename it, or use one of the five blank rows at the bottom of a table to add your own option.
A4: The workbook dropdowns read from these tables automatically. For the 0–10 Scale, keep custom entries numeric if you want averages and charts to calculate.
A6: Diagnosis Status | C6: Yes / No | E6: Yes / No / Maybe | G6: 0–10 Scale
A7: Undiagnosed / investigating | C7: Yes | E7: Yes | G7: 0
A8: Suspected autoimmune / inflammatory | C8: No | E8: No | G8: 1
A9: Newly diagnosed | E9: Maybe | G9: 2
A10: Established diagnosis | G10: 3
A11: Changing treatment | G11: 4
A12: Monitoring without medication | G12: 5
A13: Working toward remission / lower activity | G13: 6
A14: Other | G14: 7
G15: 8
G16: 9
G17: 10
A30: Day Type | C30: Yes / No / Unsure | E30: Yes / No / Partly / N/A | G30: AIP Phase
A31: Typical | C31: Yes | E31: Yes | G31: Not using AIP
A32: Flare | C32: No | E32: No | G32: Preparing
A33: Recovery | C33: Unsure | E33: Partly | G33: Elimination
A34: Better than usual | E34: Not applicable | G34: Reintroduction
A35: Unsure | G35: Personalized / maintenance
G36: Paused
A54: Symptom Change | C54: Back to Baseline | E54: Treatment Type | G54: Treatment Status
A55: New | C55: Yes | E55: Medication | G55: Active
A56: Worse | C56: No | E56: Infusion | G56: Paused
A57: Same | C57: Partly | E57: Injection | G57: Stopped
A58: Better | C58: Unsure | E58: Supplement | G58: Prescribed - not started
A59: Resolved | E59: Therapy | G59: Prescribed - access barrier
A60: Comes and goes | E60: Device | G60: Considering / discussing
E61: Nutrition / AIP
E62: Lifestyle
E63: Procedure
E64: Other
A78: Yes / No / Sometimes | C78: Treatment Event Type | E78: Nutrition Entry Type | G78: Yes / No / N/A
A79: Yes | C79: Taken / given | E79: Meal / food | G79: Yes
A80: No | C80: Missed | E80: Reintroduction test | G80: No
A81: Sometimes | C81: Held | E81: Reaction / symptom note | G81: Not applicable
C82: Delayed | E82: Plan change
C83: Dose changed | E83: Supplement / beverage
C84: Started | E84: Other
...
