Workbook
Name ApplicationSourceOptions: ApplicationSource[Application Source]
Name FeedbackTypeOptions: FeedbackType[Feedback Type]
Name InterviewStageOptions: InterviewStage[Interview Stage]
Name JobStatusOptions: JobStatus[Application Status]
Name PositionCategoryOptions: PositionCategory[Role Category]
Name RecruiterContactOptions: RecruiterContact[Recruiter Contact]
Name ResumeActivityOptions: ResumeActivity[Resume Activity]
Name ResumeVersionOptions: ResumeVersion[Resume Version]
Name SalaryRangeOptions: SalaryRange[Salary Range]
Name WorkArrangementOptions: WorkArrangement[Work Arrangement / Location]

Sheet START HERE
A1: JOB SEARCH / INTELLIGENCE TOOLKIT
A2: Free, customizable Excel tracker and visual dashboard • Created by Lora Anderson
A4: 01 RECORD APPLICATIONS
A5: In Job Applications, enter one application per row. Date, company and job title are the essentials; remaining fields are optional. The weekly helper calculates automatically. Use the salary-range dropdown if compensation was posted.
A9: 02 CUSTOMIZE DROPDOWNS
A10: On Lists, each column A–J is a separate named Excel Table. Edit the sample choices or type your own in the blank rows through row 15. Dropdown choices in Job Applications update from those tables. Keep table headers unchanged.
A14: 03 DOCUMENT EMPLOYER ENGAGEMENT
A15: Record application views, resume downloads, recruiter contacts, interview stages and feedback whenever you learn of them. If an interview later ends in rejection, keep the interview stage recorded and update Status to Rejected.
A19: 04 UNDERSTAND YOUR RESULTS
A20: Search Analytics summarizes today's application records: current outcomes, observed employer activity, interview conversion by role and resume version, salary ranges, and monthly applications. A reported view is not proof a resume was read.
A24: 05 CREATE A WEEKLY WORK-SEARCH REPORT
A25: Open Weekly Report and choose a Monday in B3. Up to 40 applications submitted that week appear below, with date, company, role, source, status and notes. Uses classic Excel functions (Excel 2010 or later), with no macros.
... A45: © 2026 Lora Anderson | Free for personal use and sharing with attribution

Sheet Job Applications
A1: Date Applied | B1: Company | C1: Job Title | D1: Location | E1: Source | F1: Job Posting URL | G1: Status | H1: Follow Up Date | I1: Contact / Recruiter | J1: Confirmation / Notes | K1: Week Starting | L1: Resume Version | M1: Role Category | N1: Resume Activity | O1: Recruiter Contact | P1: Interview Stage | Q1: Feedback Type | R1: Feedback Detail | S1: Salary Range
A2: 46300 | B2: Example Company ABC | C2: Example Job Title 1 | D2: Other | E2: Other | G2: Rejected | K2: =IF(OR(A2="",B2=""),"",A2-WEEKDAY(A2,2)+1) -> 46300 | L2: Resume 2 | M2: Category 1 | N2: Viewed | O2: Phone Call | P2: Phone Screen | Q2: None reported | S2: $50,000–$74,999
A3: 46301 | B3: Example Company XYZ | C3: Example Job Title 2 | D3: Remote | E3: Networking | G3: Interview | H3: 46305 | K3: =IF(OR(A3="",B3=""),"",A3-WEEKDAY(A3,2)+1) -> 46300 | L3: Resume 1 | M3: Category 2 | N3: Downloaded | O3: Email | P3: First Interview | S3: Under $50,000
K4: =IF(OR(A4="",B4=""),"",A4-WEEKDAY(A4,2)+1)
K5: =IF(OR(A5="",B5=""),"",A5-WEEKDAY(A5,2)+1)
K6: =IF(OR(A6="",B6=""),"",A6-WEEKDAY(A6,2)+1)
K7: =IF(OR(A7="",B7=""),"",A7-WEEKDAY(A7,2)+1)
K8: =IF(OR(A8="",B8=""),"",A8-WEEKDAY(A8,2)+1)
K9: =IF(OR(A9="",B9=""),"",A9-WEEKDAY(A9,2)+1)
K10: =IF(OR(A10="",B10=""),"",A10-WEEKDAY(A10,2)+1)
K11: =IF(OR(A11="",B11=""),"",A11-WEEKDAY(A11,2)+1)
K12: =IF(OR(A12="",B12=""),"",A12-WEEKDAY(A12,2)+1)
K13: =IF(OR(A13="",B13=""),"",A13-WEEKDAY(A13,2)+1)
K14: =IF(OR(A14="",B14=""),"",A14-WEEKDAY(A14,2)+1)
K15: =IF(OR(A15="",B15=""),"",A15-WEEKDAY(A15,2)+1)
... K1001: =IF(OR(A1001="",B1001=""),"",A1001-WEEKDAY(A1001,2)+1)

Sheet Search Analytics
A1: JOB SEARCH / INTELLIGENCE
A2: Measure the search. Detect patterns. Learn what converts. | DO NOT EDIT
A4: APPLICATIONS | E4: OBSERVABLE ENGAGEMENT | I4: EMPLOYER RESPONSES | M4: REACHED INTERVIEW | Q4: OFFERS
A5: =COUNTIF('Job Applications'!$B$2:$B$1001,"<>") -> 2 | E5: =SUMPRODUCT(--('Job Applications'!$B$2:$B$1001<>""),--(((('Job Applications'!$N$2:$N$1001="Viewed")+('Job Applications'!$N$2:$N$1001="Downloaded")+('Job Applications'!$N$2:$N$1001="Viewed + Downloaded")+('Job Applications'!$G$2:$G$1001="Application Viewed")+('Job Applications'!$G$2:$G$1001="Resume Downloaded")))>0)) -> 2 | I5: =SUMPRODUCT(--('Job Applications'!$B$2:$B$1001<>""),--(((('Job Applications'!$O$2:$O$1001<>"")*('Job Applications'!$O$2:$O$1001<>"None reported")+('Job Applications'!$P$2:$P$1001<>"")*('Job Applications'!$P$2:$P$1001<>"None")+('Job Applications'!$G$2:$G$1001="Phone Screening")+('Job Applications'!$G$2:$G$1001="Interview")+('Job Applications'!$G$2:$G$1001="Second Interview")+('Job Applications'!$G$2:$G$1001="Final Interview")+('Job Applications'!$G$2:$G$1001="Recruiter Contacted")+('Job Applications'!$G$2:$G$1001="Offer")))>0)) -> 2 | M5: =SUMPRODUCT(--('Job Applications'!$B$2:$B$1001<>""),--(((('Job Applications'!$P$2:$P$1001<>"")*('Job Applications'!$P$2:$P$1001<>"None")+('Job Applications'!$G$2:$G$1001="Phone Screening")+('Job Applications'!$G$2:$G$1001="Interview")+('Job Applications'!$G$2:$G$1001="Second Interview")+('Job Applications'!$G$2:$G$1001="Final Interview")))>0)) -> 2 | Q5: =COUNTIFS('Job Applications'!$B$2:$B$1001,"<>",'Job Applications'!$G$2:$G$1001,"Offer") -> 0
A9: APPLICATION ENGAGEMENT / FUNNEL | K9: APPLICATIONS BY MONTH / FROM YOUR FIRST APPLICATION
A10: Stage | B10: Applications | K10: Month | L10: Applications | M10: Chart Month
A11: Submitted | B11: =A5 -> 2 | K11: =IF(COUNT('Job Applications'!$A$2:$A$1001)=0,"",DATE(YEAR(MIN('Job Applications'!$A$2:$A$1001)),MONTH(MIN('Job Applications'!$A$2:$A$1001)),1)) -> 46296 | L11: =IF(K11="","",COUNTIFS('Job Applications'!$B$2:$B$1001,"<>",'Job Applications'!$A$2:$A$1001,">="&K11,'Job Applications'!$A$2:$A$1001,"<"&EDATE(K11,1))) -> 2 | M11: =IF(K11="","",TEXT(K11,"mmm yy")) -> Oct 26
A12: Viewed / Downloaded | B12: =E5 -> 2 | K12: =IF(K11="","",EDATE(K11,1)) -> 46327 | L12: =IF(K12="","",COUNTIFS('Job Applications'!$B$2:$B$1001,"<>",'Job Applications'!$A$2:$A$1001,">="&K12,'Job Applications'!$A$2:$A$1001,"<"&EDATE(K12,1))) -> 0 | M12: =IF(K12="","",TEXT(K12,"mmm yy")) -> Nov 26
A13: Employer Response | B13: =I5 -> 2 | K13: =IF(K12="","",EDATE(K12,1)) -> 46357 | L13: =IF(K13="","",COUNTIFS('Job Applications'!$B$2:$B$1001,"<>",'Job Applications'!$A$2:$A$1001,">="&K13,'Job Applications'!$A$2:$A$1001,"<"&EDATE(K13,1))) -> 0 | M13: =IF(K13="","",TEXT(K13,"mmm yy")) -> Dec 26
A14: Reached Interview | B14: =M5 -> 2 | K14: =IF(K13="","",EDATE(K13,1)) -> 46388 | L14: =IF(K14="","",COUNTIFS('Job Applications'!$B$2:$B$1001,"<>",'Job Applications'!$A$2:$A$1001,">="&K14,'Job Applications'!$A$2:$A$1001,"<"&EDATE(K14,1))) -> 0 | M14: =IF(K14="","",TEXT(K14,"mmm yy")) -> Jan 27
A15: Offers | B15: =Q5 -> 0 | K15: =IF(K14="","",EDATE(K14,1)) -> 46419 | L15: =IF(K15="","",COUNTIFS('Job Applications'!$B$2:$B$1001,"<>",'Job Applications'!$A$2:$A$1001,">="&K15,'Job Applications'!$A$2:$A$1001,"<"&EDATE(K15,1))) -> 0 | M15: =IF(K15="","",TEXT(K15,"mmm yy")) -> Feb 27
A16: Rejected | B16: =COUNTIFS('Job Applications'!$B$2:$B$1001,"<>",'Job Applications'!$G$2:$G$1001,"Rejected") -> 1 | K16: =IF(K15="","",EDATE(K15,1)) -> 46447 | L16: =IF(K16="","",COUNTIFS('Job Applications'!$B$2:$B$1001,"<>",'Job Applications'!$A$2:$A$1001,">="&K16,'Job Applications'!$A$2:$A$1001,"<"&EDATE(K16,1))) -> 0 | M16: =IF(K16="","",TEXT(K16,"mmm yy")) -> Mar 27
K17: =IF(K16="","",EDATE(K16,1)) -> 46478 | L17: =IF(K17="","",COUNTIFS('Job Applications'!$B$2:$B$1001,"<>",'Job Applications'!$A$2:$A$1001,">="&K17,'Job Applications'!$A$2:$A$1001,"<"&EDATE(K17,1))) -> 0 | M17: =IF(K17="","",TEXT(K17,"mmm yy")) -> Apr 27
K18: =IF(K17="","",EDATE(K17,1)) -> 46508 | L18: =IF(K18="","",COUNTIFS('Job Applications'!$B$2:$B$1001,"<>",'Job Applications'!$A$2:$A$1001,">="&K18,'Job Applications'!$A$2:$A$1001,"<"&EDATE(K18,1))) -> 0 | M18: =IF(K18="","",TEXT(K18,"mmm yy")) -> May 27
K19: =IF(K18="","",EDATE(K18,1)) -> 46539 | L19: =IF(K19="","",COUNTIFS('Job Applications'!$B$2:$B$1001,"<>",'Job Applications'!$A$2:$A$1001,">="&K19,'Job Applications'!$A$2:$A$1001,"<"&EDATE(K19,1))) -> 0 | M19: =IF(K19="","",TEXT(K19,"mmm yy")) -> Jun 27
K20: =IF(K19="","",EDATE(K19,1)) -> 46569 | L20: =IF(K20="","",COUNTIFS('Job Applications'!$B$2:$B$1001,"<>",'Job Applications'!$A$2:$A$1001,">="&K20,'Job Applications'!$A$2:$A$1001,"<"&EDATE(K20,1))) -> 0 | M20: =IF(K20="","",TEXT(K20,"mmm yy")) -> Jul 27
K21: =IF(K20="","",EDATE(K20,1)) -> 46600 | L21: =IF(K21="","",COUNTIFS('Job Applications'!$B$2:$B$1001,"<>",'Job Applications'!$A$2:$A$1001,">="&K21,'Job Applications'!$A$2:$A$1001,"<"&EDATE(K21,1))) -> 0 | M21: =IF(K21="","",TEXT(K21,"mmm yy")) -> Aug 27
K22: =IF(K21="","",EDATE(K21,1)) -> 46631 | L22: =IF(K22="","",COUNTIFS('Job Applications'!$B$2:$B$1001,"<>",'Job Applications'!$A$2:$A$1001,">="&K22,'Job Applications'!$A$2:$A$1001,"<"&EDATE(K22,1))) -> 0 | M22: =IF(K22="","",TEXT(K22,"mmm yy")) -> Sep 27
A26: CONVERSION BY ROLE CATEGORY | K26: CONVERSION BY RESUME VERSION | R26: SALARY RANGE SUMMARY
A27: Role category | B27: Applied | C27: Interviewed | D27: Interview rate | K27: Resume version | L27: Applied | M27: Interviewed | N27: Interview rate | R27: Advertised salary | S27: Applied | T27: Interviewed | U27: Interview rate
A28: =IF(Lists!E2="","",Lists!E2) -> Category 1 | B28: =IF(A28="","",COUNTIFS('Job Applications'!$B$2:$B$1001,"<>",'Job Applications'!$M$2:$M$1001,A28)) -> 1 | C28: =IF(A28="","",SUMPRODUCT(--('Job Applications'!$B$2:$B$1001<>""),--('Job Applications'!$M$2:$M$1001=A28),--((('Job Applications'!$P$2:$P$1001<>"")*('Job Applications'!$P$2:$P$1001<>"None")+('Job Applications'!$G$2:$G$1001="Phone Screening")+('Job Applications'!$G$2:$G$1001="Interview")+('Job Applications'!$G$2:$G$1001="Second Interview")+('Job Applications'!$G$2:$G$1001="Final Interview"))>0))) -> 1 | D28: =IFERROR(C28/B28,"") -> 1 | K28: =IF(Lists!D2="","",Lists!D2) -> Resume 1 | L28: =IF(K28="","",COUNTIFS('Job Applications'!$B$2:$B$1001,"<>",'Job Applications'!$L$2:$L$1001,K28)) -> 1 | M28: =IF(K28="","",SUMPRODUCT(--('Job Applications'!$B$2:$B$1001<>""),--('Job Applications'!$L$2:$L$1001=K28),--((('Job Applications'!$P$2:$P$1001<>"")*('Job Applications'!$P$2:$P$1001<>"None")+('Job Applications'!$G$2:$G$1001="Phone Screening")+('Job Applications'!$G$2:$G$1001="Interview")+('Job Applications'!$G$2:$G$1001="Second Interview")+('Job Applications'!$G$2:$G$1001="Final Interview"))>0))) -> 1 | N28: =IFERROR(M28/L28,"") -> 1 | R28: =IF(Lists!J2="","",Lists!J2) -> Under $50,000 | S28: =IF(R28="","",COUNTIFS('Job Applications'!$B$2:$B$1001,"<>",'Job Applications'!$S$2:$S$1001,R28)) -> 1 | T28: =IF(R28="","",SUMPRODUCT(--('Job Applications'!$B$2:$B$1001<>""),--('Job Applications'!$S$2:$S$1001=R28),--((('Job Applications'!$P$2:$P$1001<>"")*('Job Applications'!$P$2:$P$1001<>"None")+('Job Applications'!$G$2:$G$1001="Phone Screening")+('Job Applications'!$G$2:$G$1001="Interview")+('Job Applications'!$G$2:$G$1001="Second Interview")+('Job Applications'!$G$2:$G$1001="Final Interview"))>0))) -> 1 | U28: =IFERROR(T28/S28,"") -> 1
A29: =IF(Lists!E3="","",Lists!E3) -> Category 2 | B29: =IF(A29="","",COUNTIFS('Job Applications'!$B$2:$B$1001,"<>",'Job Applications'!$M$2:$M$1001,A29)) -> 1 | C29: =IF(A29="","",SUMPRODUCT(--('Job Applications'!$B$2:$B$1001<>""),--('Job Applications'!$M$2:$M$1001=A29),--((('Job Applications'!$P$2:$P$1001<>"")*('Job Applications'!$P$2:$P$1001<>"None")+('Job Applications'!$G$2:$G$1001="Phone Screening")+('Job Applications'!$G$2:$G$1001="Interview")+('Job Applications'!$G$2:$G$1001="Second Interview")+('Job Applications'!$G$2:$G$1001="Final Interview"))>0))) -> 1 | D29: =IFERROR(C29/B29,"") -> 1 | K29: =IF(Lists!D3="","",Lists!D3) -> Resume 2 | L29: =IF(K29="","",COUNTIFS('Job Applications'!$B$2:$B$1001,"<>",'Job Applications'!$L$2:$L$1001,K29)) -> 1 | M29: =IF(K29="","",SUMPRODUCT(--('Job Applications'!$B$2:$B$1001<>""),--('Job Applications'!$L$2:$L$1001=K29),--((('Job Applications'!$P$2:$P$1001<>"")*('Job Applications'!$P$2:$P$1001<>"None")+('Job Applications'!$G$2:$G$1001="Phone Screening")+('Job Applications'!$G$2:$G$1001="Interview")+('Job Applications'!$G$2:$G$1001="Second Interview")+('Job Applications'!$G$2:$G$1001="Final Interview"))>0))) -> 1 | N29: =IFERROR(M29/L29,"") -> 1 | R29: =IF(Lists!J3="","",Lists!J3) -> $50,000–$74,999 | S29: =IF(R29="","",COUNTIFS('Job Applications'!$B$2:$B$1001,"<>",'Job Applications'!$S$2:$S$1001,R29)) -> 1 | T29: =IF(R29="","",SUMPRODUCT(--('Job Applications'!$B$2:$B$1001<>""),--('Job Applications'!$S$2:$S$1001=R29),--((('Job Applications'!$P$2:$P$1001<>"")*('Job Applications'!$P$2:$P$1001<>"None")+('Job Applications'!$G$2:$G$1001="Phone Screening")+('Job Applications'!$G$2:$G$1001="Interview")+('Job Applications'!$G$2:$G$1001="Second Interview")+('Job Applications'!$G$2:$G$1001="Final Interview"))>0))) -> 1 | U29: =IFERROR(T29/S29,"") -> 1
A30: =IF(Lists!E4="","",Lists!E4) -> Category 3 | B30: =IF(A30="","",COUNTIFS('Job Applications'!$B$2:$B$1001,"<>",'Job Applications'!$M$2:$M$1001,A30)) -> 0 | C30: =IF(A30="","",SUMPRODUCT(--('Job Applications'!$B$2:$B$1001<>""),--('Job Applications'!$M$2:$M$1001=A30),--((('Job Applications'!$P$2:$P$1001<>"")*('Job Applications'!$P$2:$P$1001<>"None")+('Job Applications'!$G$2:$G$1001="Phone Screening")+('Job Applications'!$G$2:$G$1001="Interview")+('Job Applications'!$G$2:$G$1001="Second Interview")+('Job Applications'!$G$2:$G$1001="Final Interview"))>0))) -> 0 | D30: =IFERROR(C30/B30,"") | K30: =IF(Lists!D4="","",Lists!D4) -> Resume 3 | L30: =IF(K30="","",COUNTIFS('Job Applications'!$B$2:$B$1001,"<>",'Job Applications'!$L$2:$L$1001,K30)) -> 0 | M30: =IF(K30="","",SUMPRODUCT(--('Job Applications'!$B$2:$B$1001<>""),--('Job Applications'!$L$2:$L$1001=K30),--((('Job Applications'!$P$2:$P$1001<>"")*('Job Applications'!$P$2:$P$1001<>"None")+('Job Applications'!$G$2:$G$1001="Phone Screening")+('Job Applications'!$G$2:$G$1001="Interview")+('Job Applications'!$G$2:$G$1001="Second Interview")+('Job Applications'!$G$2:$G$1001="Final Interview"))>0))) -> 0 | N30: =IFERROR(M30/L30,"") | R30: =IF(Lists!J4="","",Lists!J4) -> $75,000–$99,999 | S30: =IF(R30="","",COUNTIFS('Job Applications'!$B$2:$B$1001,"<>",'Job Applications'!$S$2:$S$1001,R30)) -> 0 | T30: =IF(R30="","",SUMPRODUCT(--('Job Applications'!$B$2:$B$1001<>""),--('Job Applications'!$S$2:$S$1001=R30),--((('Job Applications'!$P$2:$P$1001<>"")*('Job Applications'!$P$2:$P$1001<>"None")+('Job Applications'!$G$2:$G$1001="Phone Screening")+('Job Applications'!$G$2:$G$1001="Interview")+('Job Applications'!$G$2:$G$1001="Second Interview")+('Job Applications'!$G$2:$G$1001="Final Interview"))>0))) -> 0 | U30: =IFERROR(T30/S30,"")
A31: =IF(Lists!E5="","",Lists!E5) -> 3 | B31: =IF(A31="","",COUNTIFS('Job Applications'!$B$2:$B$1001,"<>",'Job Applications'!$M$2:$M$1001,A31)) -> 0 | C31: =IF(A31="","",SUMPRODUCT(--('Job Applications'!$B$2:$B$1001<>""),--('Job Applications'!$M$2:$M$1001=A31),--((('Job Applications'!$P$2:$P$1001<>"")*('Job Applications'!$P$2:$P$1001<>"None")+('Job Applications'!$G$2:$G$1001="Phone Screening")+('Job Applications'!$G$2:$G$1001="Interview")+('Job Applications'!$G$2:$G$1001="Second Interview")+('Job Applications'!$G$2:$G$1001="Final Interview"))>0))) -> 0 | D31: =IFERROR(C31/B31,"") | K31: =IF(Lists!D5="","",Lists!D5) -> Resume 4 | L31: =IF(K31="","",COUNTIFS('Job Applications'!$B$2:$B$1001,"<>",'Job Applications'!$L$2:$L$1001,K31)) -> 0 | M31: =IF(K31="","",SUMPRODUCT(--('Job Applications'!$B$2:$B$1001<>""),--('Job Applications'!$L$2:$L$1001=K31),--((('Job Applications'!$P$2:$P$1001<>"")*('Job Applications'!$P$2:$P$1001<>"None")+('Job Applications'!$G$2:$G$1001="Phone Screening")+('Job Applications'!$G$2:$G$1001="Interview")+('Job Applications'!$G$2:$G$1001="Second Interview")+('Job Applications'!$G$2:$G$1001="Final Interview"))>0))) -> 0 | N31: =IFERROR(M31/L31,"") | R31: =IF(Lists!J5="","",Lists!J5) -> $100,000–$124,999 | S31: =IF(R31="","",COUNTIFS('Job Applications'!$B$2:$B$1001,"<>",'Job Applications'!$S$2:$S$1001,R31)) -> 0 | T31: =IF(R31="","",SUMPRODUCT(--('Job Applications'!$B$2:$B$1001<>""),--('Job Applications'!$S$2:$S$1001=R31),--((('Job Applications'!$P$2:$P$1001<>"")*('Job Applications'!$P$2:$P$1001<>"None")+('Job Applications'!$G$2:$G$1001="Phone Screening")+('Job Applications'!$G$2:$G$1001="Interview")+('Job Applications'!$G$2:$G$1001="Second Interview")+('Job Applications'!$G$2:$G$1001="Final Interview"))>0))) -> 0 | U31: =IFERROR(T31/S31,"")
A32: =IF(Lists!E6="","",Lists!E6) | B32: =IF(A32="","",COUNTIFS('Job Applications'!$B$2:$B$1001,"<>",'Job Applications'!$M$2:$M$1001,A32)) | C32: =IF(A32="","",SUMPRODUCT(--('Job Applications'!$B$2:$B$1001<>""),--('Job Applications'!$M$2:$M$1001=A32),--((('Job Applications'!$P$2:$P$1001<>"")*('Job Applications'!$P$2:$P$1001<>"None")+('Job Applications'!$G$2:$G$1001="Phone Screening")+('Job Applications'!$G$2:$G$1001="Interview")+('Job Applications'!$G$2:$G$1001="Second Interview")+('Job Applications'!$G$2:$G$1001="Final Interview"))>0))) | D32: =IFERROR(C32/B32,"") | K32: =IF(Lists!D6="","",Lists!D6) | L32: =IF(K32="","",COUNTIFS('Job Applications'!$B$2:$B$1001,"<>",'Job Applications'!$L$2:$L$1001,K32)) | M32: =IF(K32="","",SUMPRODUCT(--('Job Applications'!$B$2:$B$1001<>""),--('Job Applications'!$L$2:$L$1001=K32),--((('Job Applications'!$P$2:$P$1001<>"")*('Job Applications'!$P$2:$P$1001<>"None")+('Job Applications'!$G$2:$G$1001="Phone Screening")+('Job Applications'!$G$2:$G$1001="Interview")+('Job Applications'!$G$2:$G$1001="Second Interview")+('Job Applications'!$G$2:$G$1001="Final Interview"))>0))) | N32: =IFERROR(M32/L32,"") | R32: =IF(Lists!J6="","",Lists!J6) -> $125,000–$149,999 | S32: =IF(R32="","",COUNTIFS('Job Applications'!$B$2:$B$1001,"<>",'Job Applications'!$S$2:$S$1001,R32)) -> 0 | T32: =IF(R32="","",SUMPRODUCT(--('Job Applications'!$B$2:$B$1001<>""),--('Job Applications'!$S$2:$S$1001=R32),--((('Job Applications'!$P$2:$P$1001<>"")*('Job Applications'!$P$2:$P$1001<>"None")+('Job Applications'!$G$2:$G$1001="Phone Screening")+('Job Applications'!$G$2:$G$1001="Interview")+('Job Applications'!$G$2:$G$1001="Second Interview")+('Job Applications'!$G$2:$G$1001="Final Interview"))>0))) -> 0 | U32: =IFERROR(T32/S32,"")
A33: =IF(Lists!E7="","",Lists!E7) | B33: =IF(A33="","",COUNTIFS('Job Applications'!$B$2:$B$1001,"<>",'Job Applications'!$M$2:$M$1001,A33)) | C33: =IF(A33="","",SUMPRODUCT(--('Job Applications'!$B$2:$B$1001<>""),--('Job Applications'!$M$2:$M$1001=A33),--((('Job Applications'!$P$2:$P$1001<>"")*('Job Applications'!$P$2:$P$1001<>"None")+('Job Applications'!$G$2:$G$1001="Phone Screening")+('Job Applications'!$G$2:$G$1001="Interview")+('Job Applications'!$G$2:$G$1001="Second Interview")+('Job Applications'!$G$2:$G$1001="Final Interview"))>0))) | D33: =IFERROR(C33/B33,"") | K33: =IF(Lists!D7="","",Lists!D7) | L33: =IF(K33="","",COUNTIFS('Job Applications'!$B$2:$B$1001,"<>",'Job Applications'!$L$2:$L$1001,K33)) | M33: =IF(K33="","",SUMPRODUCT(--('Job Applications'!$B$2:$B$1001<>""),--('Job Applications'!$L$2:$L$1001=K33),--((('Job Applications'!$P$2:$P$1001<>"")*('Job Applications'!$P$2:$P$1001<>"None")+('Job Applications'!$G$2:$G$1001="Phone Screening")+('Job Applications'!$G$2:$G$1001="Interview")+('Job Applications'!$G$2:$G$1001="Second Interview")+('Job Applications'!$G$2:$G$1001="Final Interview"))>0))) | N33: =IFERROR(M33/L33,"") | R33: =IF(Lists!J7="","",Lists!J7) -> $150,000–$174,999 | S33: =IF(R33="","",COUNTIFS('Job Applications'!$B$2:$B$1001,"<>",'Job Applications'!$S$2:$S$1001,R33)) -> 0 | T33: =IF(R33="","",SUMPRODUCT(--('Job Applications'!$B$2:$B$1001<>""),--('Job Applications'!$S$2:$S$1001=R33),--((('Job Applications'!$P$2:$P$1001<>"")*('Job Applications'!$P$2:$P$1001<>"None")+('Job Applications'!$G$2:$G$1001="Phone Screening")+('Job Applications'!$G$2:$G$1001="Interview")+('Job Applications'!$G$2:$G$1001="Second Interview")+('Job Applications'!$G$2:$G$1001="Final Interview"))>0))) -> 0 | U33: =IFERROR(T33/S33,"")
A34: =IF(Lists!E8="","",Lists!E8) | B34: =IF(A34="","",COUNTIFS('Job Applications'!$B$2:$B$1001,"<>",'Job Applications'!$M$2:$M$1001,A34)) | C34: =IF(A34="","",SUMPRODUCT(--('Job Applications'!$B$2:$B$1001<>""),--('Job Applications'!$M$2:$M$1001=A34),--((('Job Applications'!$P$2:$P$1001<>"")*('Job Applications'!$P$2:$P$1001<>"None")+('Job Applications'!$G$2:$G$1001="Phone Screening")+('Job Applications'!$G$2:$G$1001="Interview")+('Job Applications'!$G$2:$G$1001="Second Interview")+('Job Applications'!$G$2:$G$1001="Final Interview"))>0))) | D34: =IFERROR(C34/B34,"") | K34: =IF(Lists!D8="","",Lists!D8) | L34: =IF(K34="","",COUNTIFS('Job Applications'!$B$2:$B$1001,"<>",'Job Applications'!$L$2:$L$1001,K34)) | M34: =IF(K34="","",SUMPRODUCT(--('Job Applications'!$B$2:$B$1001<>""),--('Job Applications'!$L$2:$L$1001=K34),--((('Job Applications'!$P$2:$P$1001<>"")*('Job Applications'!$P$2:$P$1001<>"None")+('Job Applications'!$G$2:$G$1001="Phone Screening")+('Job Applications'!$G$2:$G$1001="Interview")+('Job Applications'!$G$2:$G$1001="Second Interview")+('Job Applications'!$G$2:$G$1001="Final Interview"))>0))) | N34: =IFERROR(M34/L34,"") | R34: =IF(Lists!J8="","",Lists!J8) -> $175,000–$199,999 | S34: =IF(R34="","",COUNTIFS('Job Applications'!$B$2:$B$1001,"<>",'Job Applications'!$S$2:$S$1001,R34)) -> 0 | T34: =IF(R34="","",SUMPRODUCT(--('Job Applications'!$B$2:$B$1001<>""),--('Job Applications'!$S$2:$S$1001=R34),--((('Job Applications'!$P$2:$P$1001<>"")*('Job Applications'!$P$2:$P$1001<>"None")+('Job Applications'!$G$2:$G$1001="Phone Screening")+('Job Applications'!$G$2:$G$1001="Interview")+('Job Applications'!$G$2:$G$1001="Second Interview")+('Job Applications'!$G$2:$G$1001="Final Interview"))>0))) -> 0 | U34: =IFERROR(T34/S34,"")
A35: =IF(Lists!E9="","",Lists!E9) | B35: =IF(A35="","",COUNTIFS('Job Applications'!$B$2:$B$1001,"<>",'Job Applications'!$M$2:$M$1001,A35)) | C35: =IF(A35="","",SUMPRODUCT(--('Job Applications'!$B$2:$B$1001<>""),--('Job Applications'!$M$2:$M$1001=A35),--((('Job Applications'!$P$2:$P$1001<>"")*('Job Applications'!$P$2:$P$1001<>"None")+('Job Applications'!$G$2:$G$1001="Phone Screening")+('Job Applications'!$G$2:$G$1001="Interview")+('Job Applications'!$G$2:$G$1001="Second Interview")+('Job Applications'!$G$2:$G$1001="Final Interview"))>0))) | D35: =IFERROR(C35/B35,"") | K35: =IF(Lists!D9="","",Lists!D9) | L35: =IF(K35="","",COUNTIFS('Job Applications'!$B$2:$B$1001,"<>",'Job Applications'!$L$2:$L$1001,K35)) | M35: =IF(K35="","",SUMPRODUCT(--('Job Applications'!$B$2:$B$1001<>""),--('Job Applications'!$L$2:$L$1001=K35),--((('Job Applications'!$P$2:$P$1001<>"")*('Job Applications'!$P$2:$P$1001<>"None")+('Job Applications'!$G$2:$G$1001="Phone Screening")+('Job Applications'!$G$2:$G$1001="Interview")+('Job Applications'!$G$2:$G$1001="Second Interview")+('Job Applications'!$G$2:$G$1001="Final Interview"))>0))) | N35: =IFERROR(M35/L35,"") | R35: =IF(Lists!J9="","",Lists!J9) -> $200,000+ | S35: =IF(R35="","",COUNTIFS('Job Applications'!$B$2:$B$1001,"<>",'Job Applications'!$S$2:$S$1001,R35)) -> 0 | T35: =IF(R35="","",SUMPRODUCT(--('Job Applications'!$B$2:$B$1001<>""),--('Job Applications'!$S$2:$S$1001=R35),--((('Job Applications'!$P$2:$P$1001<>"")*('Job Applications'!$P$2:$P$1001<>"None")+('Job Applications'!$G$2:$G$1001="Phone Screening")+('Job Applications'!$G$2:$G$1001="Interview")+('Job Applications'!$G$2:$G$1001="Second Interview")+('Job Applications'!$G$2:$G$1001="Final Interview"))>0))) -> 0 | U35: =IFERROR(T35/S35,"")
A36: =IF(Lists!E10="","",Lists!E10) | B36: =IF(A36="","",COUNTIFS('Job Applications'!$B$2:$B$1001,"<>",'Job Applications'!$M$2:$M$1001,A36)) | C36: =IF(A36="","",SUMPRODUCT(--('Job Applications'!$B$2:$B$1001<>""),--('Job Applications'!$M$2:$M$1001=A36),--((('Job Applications'!$P$2:$P$1001<>"")*('Job Applications'!$P$2:$P$1001<>"None")+('Job Applications'!$G$2:$G$1001="Phone Screening")+('Job Applications'!$G$2:$G$1001="Interview")+('Job Applications'!$G$2:$G$1001="Second Interview")+('Job Applications'!$G$2:$G$1001="Final Interview"))>0))) | D36: =IFERROR(C36/B36,"") | K36: =IF(Lists!D10="","",Lists!D10) | L36: =IF(K36="","",COUNTIFS('Job Applications'!$B$2:$B$1001,"<>",'Job Applications'!$L$2:$L$1001,K36)) | M36: =IF(K36="","",SUMPRODUCT(--('Job Applications'!$B$2:$B$1001<>""),--('Job Applications'!$L$2:$L$1001=K36),--((('Job Applications'!$P$2:$P$1001<>"")*('Job Applications'!$P$2:$P$1001<>"None")+('Job Applications'!$G$2:$G$1001="Phone Screening")+('Job Applications'!$G$2:$G$1001="Interview")+('Job Applications'!$G$2:$G$1001="Second Interview")+('Job Applications'!$G$2:$G$1001="Final Interview"))>0))) | N36: =IFERROR(M36/L36,"") | R36: =IF(Lists!J10="","",Lists!J10) -> Not Disclosed | S36: =IF(R36="","",COUNTIFS('Job Applications'!$B$2:$B$1001,"<>",'Job Applications'!$S$2:$S$1001,R36)) -> 0 | T36: =IF(R36="","",SUMPRODUCT(--('Job Applications'!$B$2:$B$1001<>""),--('Job Applications'!$S$2:$S$1001=R36),--((('Job Applications'!$P$2:$P$1001<>"")*('Job Applications'!$P$2:$P$1001<>"None")+('Job Applications'!$G$2:$G$1001="Phone Screening")+('Job Applications'!$G$2:$G$1001="Interview")+('Job Applications'!$G$2:$G$1001="Second Interview")+('Job Applications'!$G$2:$G$1001="Final Interview"))>0))) -> 0 | U36: =IFERROR(T36/S36,"")
A37: =IF(Lists!E11="","",Lists!E11) | B37: =IF(A37="","",COUNTIFS('Job Applications'!$B$2:$B$1001,"<>",'Job Applications'!$M$2:$M$1001,A37)) | C37: =IF(A37="","",SUMPRODUCT(--('Job Applications'!$B$2:$B$1001<>""),--('Job Applications'!$M$2:$M$1001=A37),--((('Job Applications'!$P$2:$P$1001<>"")*('Job Applications'!$P$2:$P$1001<>"None")+('Job Applications'!$G$2:$G$1001="Phone Screening")+('Job Applications'!$G$2:$G$1001="Interview")+('Job Applications'!$G$2:$G$1001="Second Interview")+('Job Applications'!$G$2:$G$1001="Final Interview"))>0))) | D37: =IFERROR(C37/B37,"") | K37: =IF(Lists!D11="","",Lists!D11) | L37: =IF(K37="","",COUNTIFS('Job Applications'!$B$2:$B$1001,"<>",'Job Applications'!$L$2:$L$1001,K37)) | M37: =IF(K37="","",SUMPRODUCT(--('Job Applications'!$B$2:$B$1001<>""),--('Job Applications'!$L$2:$L$1001=K37),--((('Job Applications'!$P$2:$P$1001<>"")*('Job Applications'!$P$2:$P$1001<>"None")+('Job Applications'!$G$2:$G$1001="Phone Screening")+('Job Applications'!$G$2:$G$1001="Interview")+('Job Applications'!$G$2:$G$1001="Second Interview")+('Job Applications'!$G$2:$G$1001="Final Interview"))>0))) | N37: =IFERROR(M37/L37,"") | R37: =IF(Lists!J11="","",Lists!J11) -> Negotiable | S37: =IF(R37="","",COUNTIFS('Job Applications'!$B$2:$B$1001,"<>",'Job Applications'!$S$2:$S$1001,R37)) -> 0 | T37: =IF(R37="","",SUMPRODUCT(--('Job Applications'!$B$2:$B$1001<>""),--('Job Applications'!$S$2:$S$1001=R37),--((('Job Applications'!$P$2:$P$1001<>"")*('Job Applications'!$P$2:$P$1001<>"None")+('Job Applications'!$G$2:$G$1001="Phone Screening")+('Job Applications'!$G$2:$G$1001="Interview")+('Job Applications'!$G$2:$G$1001="Second Interview")+('Job Applications'!$G$2:$G$1001="Final Interview"))>0))) -> 0 | U37: =IFERROR(T37/S37,"")
A38: =IF(Lists!E12="","",Lists!E12) | B38: =IF(A38="","",COUNTIFS('Job Applications'!$B$2:$B$1001,"<>",'Job Applications'!$M$2:$M$1001,A38)) | C38: =IF(A38="","",SUMPRODUCT(--('Job Applications'!$B$2:$B$1001<>""),--('Job Applications'!$M$2:$M$1001=A38),--((('Job Applications'!$P$2:$P$1001<>"")*('Job Applications'!$P$2:$P$1001<>"None")+('Job Applications'!$G$2:$G$1001="Phone Screening")+('Job Applications'!$G$2:$G$1001="Interview")+('Job Applications'!$G$2:$G$1001="Second Interview")+('Job Applications'!$G$2:$G$1001="Final Interview"))>0))) | D38: =IFERROR(C38/B38,"") | K38: =IF(Lists!D12="","",Lists!D12) | L38: =IF(K38="","",COUNTIFS('Job Applications'!$B$2:$B$1001,"<>",'Job Applications'!$L$2:$L$1001,K38)) | M38: =IF(K38="","",SUMPRODUCT(--('Job Applications'!$B$2:$B$1001<>""),--('Job Applications'!$L$2:$L$1001=K38),--((('Job Applications'!$P$2:$P$1001<>"")*('Job Applications'!$P$2:$P$1001<>"None")+('Job Applications'!$G$2:$G$1001="Phone Screening")+('Job Applications'!$G$2:$G$1001="Interview")+('Job Applications'!$G$2:$G$1001="Second Interview")+('Job Applications'!$G$2:$G$1001="Final Interview"))>0))) | N38: =IFERROR(M38/L38,"") | R38: =IF(Lists!J12="","",Lists!J12) | S38: =IF(R38="","",COUNTIFS('Job Applications'!$B$2:$B$1001,"<>",'Job Applications'!$S$2:$S$1001,R38)) | T38: =IF(R38="","",SUMPRODUCT(--('Job Applications'!$B$2:$B$1001<>""),--('Job Applications'!$S$2:$S$1001=R38),--((('Job Applications'!$P$2:$P$1001<>"")*('Job Applications'!$P$2:$P$1001<>"None")+('Job Applications'!$G$2:$G$1001="Phone Screening")+('Job Applications'!$G$2:$G$1001="Interview")+('Job Applications'!$G$2:$G$1001="Second Interview")+('Job Applications'!$G$2:$G$1001="Final Interview"))>0))) | U38: =IFERROR(T38/S38,"")
A39: =IF(Lists!E13="","",Lists!E13) | B39: =IF(A39="","",COUNTIFS('Job Applications'!$B$2:$B$1001,"<>",'Job Applications'!$M$2:$M$1001,A39)) | C39: =IF(A39="","",SUMPRODUCT(--('Job Applications'!$B$2:$B$1001<>""),--('Job Applications'!$M$2:$M$1001=A39),--((('Job Applications'!$P$2:$P$1001<>"")*('Job Applications'!$P$2:$P$1001<>"None")+('Job Applications'!$G$2:$G$1001="Phone Screening")+('Job Applications'!$G$2:$G$1001="Interview")+('Job Applications'!$G$2:$G$1001="Second Interview")+('Job Applications'!$G$2:$G$1001="Final Interview"))>0))) | D39: =IFERROR(C39/B39,"") | K39: =IF(Lists!D13="","",Lists!D13) | L39: =IF(K39="","",COUNTIFS('Job Applications'!$B$2:$B$1001,"<>",'Job Applications'!$L$2:$L$1001,K39)) | M39: =IF(K39="","",SUMPRODUCT(--('Job Applications'!$B$2:$B$1001<>""),--('Job Applications'!$L$2:$L$1001=K39),--((('Job Applications'!$P$2:$P$1001<>"")*('Job Applications'!$P$2:$P$1001<>"None")+('Job Applications'!$G$2:$G$1001="Phone Screening")+('Job Applications'!$G$2:$G$1001="Interview")+('Job Applications'!$G$2:$G$1001="Second Interview")+('Job Applications'!$G$2:$G$1001="Final Interview"))>0))) | N39: =IFERROR(M39/L39,"") | R39: =IF(Lists!J13="","",Lists!J13) | S39: =IF(R39="","",COUNTIFS('Job Applications'!$B$2:$B$1001,"<>",'Job Applications'!$S$2:$S$1001,R39)) | T39: =IF(R39="","",SUMPRODUCT(--('Job Applications'!$B$2:$B$1001<>""),--('Job Applications'!$S$2:$S$1001=R39),--((('Job Applications'!$P$2:$P$1001<>"")*('Job Applications'!$P$2:$P$1001<>"None")+('Job Applications'!$G$2:$G$1001="Phone Screening")+('Job Applications'!$G$2:$G$1001="Interview")+('Job Applications'!$G$2:$G$1001="Second Interview")+('Job Applications'!$G$2:$G$1001="Final Interview"))>0))) | U39: =IFERROR(T39/S39,"")
... A41: =IF(Lists!E15="","",Lists!E15) | B41: =IF(A41="","",COUNTIFS('Job Applications'!$B$2:$B$1001,"<>",'Job Applications'!$M$2:$M$1001,A41)) | C41: =IF(A41="","",SUMPRODUCT(--('Job Applications'!$B$2:$B$1001<>""),--('Job Applications'!$M$2:$M$1001=A41),--((('Job Applications'!$P$2:$P$1001<>"")*('Job Applications'!$P$2:$P$1001<>"None")+('Job Applications'!$G$2:$G$1001="Phone Screening")+('Job Applications'!$G$2:$G$1001="Interview")+('Job Applications'!$G$2:$G$1001="Second Interview")+('Job Applications'!$G$2:$G$1001="Final Interview"))>0))) | D41: =IFERROR(C41/B41,"") | K41: =IF(Lists!D15="","",Lists!D15) | L41: =IF(K41="","",COUNTIFS('Job Applications'!$B$2:$B$1001,"<>",'Job Applications'!$L$2:$L$1001,K41)) | M41: =IF(K41="","",SUMPRODUCT(--('Job Applications'!$B$2:$B$1001<>""),--('Job Applications'!$L$2:$L$1001=K41),--((('Job Applications'!$P$2:$P$1001<>"")*('Job Applications'!$P$2:$P$1001<>"None")+('Job Applications'!$G$2:$G$1001="Phone Screening")+('Job Applications'!$G$2:$G$1001="Interview")+('Job Applications'!$G$2:$G$1001="Second Interview")+('Job Applications'!$G$2:$G$1001="Final Interview"))>0))) | N41: =IFERROR(M41/L41,"") | R41: =IF(Lists!J15="","",Lists!J15) | S41: =IF(R41="","",COUNTIFS('Job Applications'!$B$2:$B$1001,"<>",'Job Applications'!$S$2:$S$1001,R41)) | T41: =IF(R41="","",SUMPRODUCT(--('Job Applications'!$B$2:$B$1001<>""),--('Job Applications'!$S$2:$S$1001=R41),--((('Job Applications'!$P$2:$P$1001<>"")*('Job Applications'!$P$2:$P$1001<>"None")+('Job Applications'!$G$2:$G$1001="Phone Screening")+('Job Applications'!$G$2:$G$1001="Interview")+('Job Applications'!$G$2:$G$1001="Second Interview")+('Job Applications'!$G$2:$G$1001="Final Interview"))>0))) | U41: =IFERROR(T41/S41,"")
A50: JOB SEARCH INTELLIGENCE TOOLKIT • CREATED BY LORA ANDERSON • FREE RESOURCE
A81: READ THIS BEFORE INTERPRETING THE DASHBOARD
A83: Engagement = an application platform reported a view/download; not confirmation a human read your resume.
A84: Contact and interview metrics count each application at most once; missing employer signals do not prove inactivity.
A85: Applications by month are grouped by date applied; the most recent months have had less time to progress.
A86: Interview rate = applications reaching a phone/interview stage divided by applications with that category.
A87: Advertised salary bands use annualized range midpoints. Adjust hourly assumptions and thresholds on Lists.
...

Sheet Weekly Report
A1: WEEKLY / JOB SEARCH REPORT | H1: Report helper
A2: Choose a Monday in B3 to show applications submitted during that week.
A3: Week Starting | B3: =TODAY()-WEEKDAY(TODAY(),2)+1 -> 46300 | D3: Applications this week | E3: =COUNTIFS('Job Applications'!$K$2:$K$1001,$B$3,'Job Applications'!$B$2:$B$1001,"<>") -> 2
A5: Date Applied | B5: Company | C5: Job Title | D5: Source | E5: Status | F5: Notes
A6: =IF($H6="","",IF(INDEX('Job Applications'!$A$2:$A$1001,$H6)="","",INDEX('Job Applications'!$A$2:$A$1001,$H6))) -> 46300 | B6: =IF($H6="","",IF(INDEX('Job Applications'!$B$2:$B$1001,$H6)="","",INDEX('Job Applications'!$B$2:$B$1001,$H6))) -> Example Company ABC | C6: =IF($H6="","",IF(INDEX('Job Applications'!$C$2:$C$1001,$H6)="","",INDEX('Job Applications'!$C$2:$C$1001,$H6))) -> Example Job Title 1 | D6: =IF($H6="","",IF(INDEX('Job Applications'!$E$2:$E$1001,$H6)="","",INDEX('Job Applications'!$E$2:$E$1001,$H6))) -> Other | E6: =IF($H6="","",IF(INDEX('Job Applications'!$G$2:$G$1001,$H6)="","",INDEX('Job Applications'!$G$2:$G$1001,$H6))) -> Rejected | F6: =IF($H6="","",IF(INDEX('Job Applications'!$J$2:$J$1001,$H6)="","",INDEX('Job Applications'!$J$2:$J$1001,$H6))) | H6: =IFERROR(_xlfn.AGGREGATE(15,6,(ROW('Job Applications'!$K$2:$K$1001)-ROW('Job Applications'!$K$2)+1)/(('Job Applications'!$K$2:$K$1001=$B$3)*('Job Applications'!$B$2:$B$1001<>"")),ROWS($H$6:H6)),"") -> 1
A7: =IF($H7="","",IF(INDEX('Job Applications'!$A$2:$A$1001,$H7)="","",INDEX('Job Applications'!$A$2:$A$1001,$H7))) -> 46301 | B7: =IF($H7="","",IF(INDEX('Job Applications'!$B$2:$B$1001,$H7)="","",INDEX('Job Applications'!$B$2:$B$1001,$H7))) -> Example Company XYZ | C7: =IF($H7="","",IF(INDEX('Job Applications'!$C$2:$C$1001,$H7)="","",INDEX('Job Applications'!$C$2:$C$1001,$H7))) -> Example Job Title 2 | D7: =IF($H7="","",IF(INDEX('Job Applications'!$E$2:$E$1001,$H7)="","",INDEX('Job Applications'!$E$2:$E$1001,$H7))) -> Networking | E7: =IF($H7="","",IF(INDEX('Job Applications'!$G$2:$G$1001,$H7)="","",INDEX('Job Applications'!$G$2:$G$1001,$H7))) -> Interview | F7: =IF($H7="","",IF(INDEX('Job Applications'!$J$2:$J$1001,$H7)="","",INDEX('Job Applications'!$J$2:$J$1001,$H7))) | H7: =IFERROR(_xlfn.AGGREGATE(15,6,(ROW('Job Applications'!$K$2:$K$1001)-ROW('Job Applications'!$K$2)+1)/(('Job Applications'!$K$2:$K$1001=$B$3)*('Job Applications'!$B$2:$B$1001<>"")),ROWS($H$6:H7)),"") -> 2
A8: =IF($H8="","",IF(INDEX('Job Applications'!$A$2:$A$1001,$H8)="","",INDEX('Job Applications'!$A$2:$A$1001,$H8))) | B8: =IF($H8="","",IF(INDEX('Job Applications'!$B$2:$B$1001,$H8)="","",INDEX('Job Applications'!$B$2:$B$1001,$H8))) | C8: =IF($H8="","",IF(INDEX('Job Applications'!$C$2:$C$1001,$H8)="","",INDEX('Job Applications'!$C$2:$C$1001,$H8))) | D8: =IF($H8="","",IF(INDEX('Job Applications'!$E$2:$E$1001,$H8)="","",INDEX('Job Applications'!$E$2:$E$1001,$H8))) | E8: =IF($H8="","",IF(INDEX('Job Applications'!$G$2:$G$1001,$H8)="","",INDEX('Job Applications'!$G$2:$G$1001,$H8))) | F8: =IF($H8="","",IF(INDEX('Job Applications'!$J$2:$J$1001,$H8)="","",INDEX('Job Applications'!$J$2:$J$1001,$H8))) | H8: =IFERROR(_xlfn.AGGREGATE(15,6,(ROW('Job Applications'!$K$2:$K$1001)-ROW('Job Applications'!$K$2)+1)/(('Job Applications'!$K$2:$K$1001=$B$3)*('Job Applications'!$B$2:$B$1001<>"")),ROWS($H$6:H8)),"")
A9: =IF($H9="","",IF(INDEX('Job Applications'!$A$2:$A$1001,$H9)="","",INDEX('Job Applications'!$A$2:$A$1001,$H9))) | B9: =IF($H9="","",IF(INDEX('Job Applications'!$B$2:$B$1001,$H9)="","",INDEX('Job Applications'!$B$2:$B$1001,$H9))) | C9: =IF($H9="","",IF(INDEX('Job Applications'!$C$2:$C$1001,$H9)="","",INDEX('Job Applications'!$C$2:$C$1001,$H9))) | D9: =IF($H9="","",IF(INDEX('Job Applications'!$E$2:$E$1001,$H9)="","",INDEX('Job Applications'!$E$2:$E$1001,$H9))) | E9: =IF($H9="","",IF(INDEX('Job Applications'!$G$2:$G$1001,$H9)="","",INDEX('Job Applications'!$G$2:$G$1001,$H9))) | F9: =IF($H9="","",IF(INDEX('Job Applications'!$J$2:$J$1001,$H9)="","",INDEX('Job Applications'!$J$2:$J$1001,$H9))) | H9: =IFERROR(_xlfn.AGGREGATE(15,6,(ROW('Job Applications'!$K$2:$K$1001)-ROW('Job Applications'!$K$2)+1)/(('Job Applications'!$K$2:$K$1001=$B$3)*('Job Applications'!$B$2:$B$1001<>"")),ROWS($H$6:H9)),"")
A10: =IF($H10="","",IF(INDEX('Job Applications'!$A$2:$A$1001,$H10)="","",INDEX('Job Applications'!$A$2:$A$1001,$H10))) | B10: =IF($H10="","",IF(INDEX('Job Applications'!$B$2:$B$1001,$H10)="","",INDEX('Job Applications'!$B$2:$B$1001,$H10))) | C10: =IF($H10="","",IF(INDEX('Job Applications'!$C$2:$C$1001,$H10)="","",INDEX('Job Applications'!$C$2:$C$1001,$H10))) | D10: =IF($H10="","",IF(INDEX('Job Applications'!$E$2:$E$1001,$H10)="","",INDEX('Job Applications'!$E$2:$E$1001,$H10))) | E10: =IF($H10="","",IF(INDEX('Job Applications'!$G$2:$G$1001,$H10)="","",INDEX('Job Applications'!$G$2:$G$1001,$H10))) | F10: =IF($H10="","",IF(INDEX('Job Applications'!$J$2:$J$1001,$H10)="","",INDEX('Job Applications'!$J$2:$J$1001,$H10))) | H10: =IFERROR(_xlfn.AGGREGATE(15,6,(ROW('Job Applications'!$K$2:$K$1001)-ROW('Job Applications'!$K$2)+1)/(('Job Applications'!$K$2:$K$1001=$B$3)*('Job Applications'!$B$2:$B$1001<>"")),ROWS($H$6:H10)),"")
A11: =IF($H11="","",IF(INDEX('Job Applications'!$A$2:$A$1001,$H11)="","",INDEX('Job Applications'!$A$2:$A$1001,$H11))) | B11: =IF($H11="","",IF(INDEX('Job Applications'!$B$2:$B$1001,$H11)="","",INDEX('Job Applications'!$B$2:$B$1001,$H11))) | C11: =IF($H11="","",IF(INDEX('Job Applications'!$C$2:$C$1001,$H11)="","",INDEX('Job Applications'!$C$2:$C$1001,$H11))) | D11: =IF($H11="","",IF(INDEX('Job Applications'!$E$2:$E$1001,$H11)="","",INDEX('Job Applications'!$E$2:$E$1001,$H11))) | E11: =IF($H11="","",IF(INDEX('Job Applications'!$G$2:$G$1001,$H11)="","",INDEX('Job Applications'!$G$2:$G$1001,$H11))) | F11: =IF($H11="","",IF(INDEX('Job Applications'!$J$2:$J$1001,$H11)="","",INDEX('Job Applications'!$J$2:$J$1001,$H11))) | H11: =IFERROR(_xlfn.AGGREGATE(15,6,(ROW('Job Applications'!$K$2:$K$1001)-ROW('Job Applications'!$K$2)+1)/(('Job Applications'!$K$2:$K$1001=$B$3)*('Job Applications'!$B$2:$B$1001<>"")),ROWS($H$6:H11)),"")
A12: =IF($H12="","",IF(INDEX('Job Applications'!$A$2:$A$1001,$H12)="","",INDEX('Job Applications'!$A$2:$A$1001,$H12))) | B12: =IF($H12="","",IF(INDEX('Job Applications'!$B$2:$B$1001,$H12)="","",INDEX('Job Applications'!$B$2:$B$1001,$H12))) | C12: =IF($H12="","",IF(INDEX('Job Applications'!$C$2:$C$1001,$H12)="","",INDEX('Job Applications'!$C$2:$C$1001,$H12))) | D12: =IF($H12="","",IF(INDEX('Job Applications'!$E$2:$E$1001,$H12)="","",INDEX('Job Applications'!$E$2:$E$1001,$H12))) | E12: =IF($H12="","",IF(INDEX('Job Applications'!$G$2:$G$1001,$H12)="","",INDEX('Job Applications'!$G$2:$G$1001,$H12))) | F12: =IF($H12="","",IF(INDEX('Job Applications'!$J$2:$J$1001,$H12)="","",INDEX('Job Applications'!$J$2:$J$1001,$H12))) | H12: =IFERROR(_xlfn.AGGREGATE(15,6,(ROW('Job Applications'!$K$2:$K$1001)-ROW('Job Applications'!$K$2)+1)/(('Job Applications'!$K$2:$K$1001=$B$3)*('Job Applications'!$B$2:$B$1001<>"")),ROWS($H$6:H12)),"")
A13: =IF($H13="","",IF(INDEX('Job Applications'!$A$2:$A$1001,$H13)="","",INDEX('Job Applications'!$A$2:$A$1001,$H13))) | B13: =IF($H13="","",IF(INDEX('Job Applications'!$B$2:$B$1001,$H13)="","",INDEX('Job Applications'!$B$2:$B$1001,$H13))) | C13: =IF($H13="","",IF(INDEX('Job Applications'!$C$2:$C$1001,$H13)="","",INDEX('Job Applications'!$C$2:$C$1001,$H13))) | D13: =IF($H13="","",IF(INDEX('Job Applications'!$E$2:$E$1001,$H13)="","",INDEX('Job Applications'!$E$2:$E$1001,$H13))) | E13: =IF($H13="","",IF(INDEX('Job Applications'!$G$2:$G$1001,$H13)="","",INDEX('Job Applications'!$G$2:$G$1001,$H13))) | F13: =IF($H13="","",IF(INDEX('Job Applications'!$J$2:$J$1001,$H13)="","",INDEX('Job Applications'!$J$2:$J$1001,$H13))) | H13: =IFERROR(_xlfn.AGGREGATE(15,6,(ROW('Job Applications'!$K$2:$K$1001)-ROW('Job Applications'!$K$2)+1)/(('Job Applications'!$K$2:$K$1001=$B$3)*('Job Applications'!$B$2:$B$1001<>"")),ROWS($H$6:H13)),"")
A14: =IF($H14="","",IF(INDEX('Job Applications'!$A$2:$A$1001,$H14)="","",INDEX('Job Applications'!$A$2:$A$1001,$H14))) | B14: =IF($H14="","",IF(INDEX('Job Applications'!$B$2:$B$1001,$H14)="","",INDEX('Job Applications'!$B$2:$B$1001,$H14))) | C14: =IF($H14="","",IF(INDEX('Job Applications'!$C$2:$C$1001,$H14)="","",INDEX('Job Applications'!$C$2:$C$1001,$H14))) | D14: =IF($H14="","",IF(INDEX('Job Applications'!$E$2:$E$1001,$H14)="","",INDEX('Job Applications'!$E$2:$E$1001,$H14))) | E14: =IF($H14="","",IF(INDEX('Job Applications'!$G$2:$G$1001,$H14)="","",INDEX('Job Applications'!$G$2:$G$1001,$H14))) | F14: =IF($H14="","",IF(INDEX('Job Applications'!$J$2:$J$1001,$H14)="","",INDEX('Job Applications'!$J$2:$J$1001,$H14))) | H14: =IFERROR(_xlfn.AGGREGATE(15,6,(ROW('Job Applications'!$K$2:$K$1001)-ROW('Job Applications'!$K$2)+1)/(('Job Applications'!$K$2:$K$1001=$B$3)*('Job Applications'!$B$2:$B$1001<>"")),ROWS($H$6:H14)),"")
A15: =IF($H15="","",IF(INDEX('Job Applications'!$A$2:$A$1001,$H15)="","",INDEX('Job Applications'!$A$2:$A$1001,$H15))) | B15: =IF($H15="","",IF(INDEX('Job Applications'!$B$2:$B$1001,$H15)="","",INDEX('Job Applications'!$B$2:$B$1001,$H15))) | C15: =IF($H15="","",IF(INDEX('Job Applications'!$C$2:$C$1001,$H15)="","",INDEX('Job Applications'!$C$2:$C$1001,$H15))) | D15: =IF($H15="","",IF(INDEX('Job Applications'!$E$2:$E$1001,$H15)="","",INDEX('Job Applications'!$E$2:$E$1001,$H15))) | E15: =IF($H15="","",IF(INDEX('Job Applications'!$G$2:$G$1001,$H15)="","",INDEX('Job Applications'!$G$2:$G$1001,$H15))) | F15: =IF($H15="","",IF(INDEX('Job Applications'!$J$2:$J$1001,$H15)="","",INDEX('Job Applications'!$J$2:$J$1001,$H15))) | H15: =IFERROR(_xlfn.AGGREGATE(15,6,(ROW('Job Applications'!$K$2:$K$1001)-ROW('Job Applications'!$K$2)+1)/(('Job Applications'!$K$2:$K$1001=$B$3)*('Job Applications'!$B$2:$B$1001<>"")),ROWS($H$6:H15)),"")
A16: =IF($H16="","",IF(INDEX('Job Applications'!$A$2:$A$1001,$H16)="","",INDEX('Job Applications'!$A$2:$A$1001,$H16))) | B16: =IF($H16="","",IF(INDEX('Job Applications'!$B$2:$B$1001,$H16)="","",INDEX('Job Applications'!$B$2:$B$1001,$H16))) | C16: =IF($H16="","",IF(INDEX('Job Applications'!$C$2:$C$1001,$H16)="","",INDEX('Job Applications'!$C$2:$C$1001,$H16))) | D16: =IF($H16="","",IF(INDEX('Job Applications'!$E$2:$E$1001,$H16)="","",INDEX('Job Applications'!$E$2:$E$1001,$H16))) | E16: =IF($H16="","",IF(INDEX('Job Applications'!$G$2:$G$1001,$H16)="","",INDEX('Job Applications'!$G$2:$G$1001,$H16))) | F16: =IF($H16="","",IF(INDEX('Job Applications'!$J$2:$J$1001,$H16)="","",INDEX('Job Applications'!$J$2:$J$1001,$H16))) | H16: =IFERROR(_xlfn.AGGREGATE(15,6,(ROW('Job Applications'!$K$2:$K$1001)-ROW('Job Applications'!$K$2)+1)/(('Job Applications'!$K$2:$K$1001=$B$3)*('Job Applications'!$B$2:$B$1001<>"")),ROWS($H$6:H16)),"")
A17: =IF($H17="","",IF(INDEX('Job Applications'!$A$2:$A$1001,$H17)="","",INDEX('Job Applications'!$A$2:$A$1001,$H17))) | B17: =IF($H17="","",IF(INDEX('Job Applications'!$B$2:$B$1001,$H17)="","",INDEX('Job Applications'!$B$2:$B$1001,$H17))) | C17: =IF($H17="","",IF(INDEX('Job Applications'!$C$2:$C$1001,$H17)="","",INDEX('Job Applications'!$C$2:$C$1001,$H17))) | D17: =IF($H17="","",IF(INDEX('Job Applications'!$E$2:$E$1001,$H17)="","",INDEX('Job Applications'!$E$2:$E$1001,$H17))) | E17: =IF($H17="","",IF(INDEX('Job Applications'!$G$2:$G$1001,$H17)="","",INDEX('Job Applications'!$G$2:$G$1001,$H17))) | F17: =IF($H17="","",IF(INDEX('Job Applications'!$J$2:$J$1001,$H17)="","",INDEX('Job Applications'!$J$2:$J$1001,$H17))) | H17: =IFERROR(_xlfn.AGGREGATE(15,6,(ROW('Job Applications'!$K$2:$K$1001)-ROW('Job Applications'!$K$2)+1)/(('Job Applications'!$K$2:$K$1001=$B$3)*('Job Applications'!$B$2:$B$1001<>"")),ROWS($H$6:H17)),"")
... A45: =IF($H45="","",IF(INDEX('Job Applications'!$A$2:$A$1001,$H45)="","",INDEX('Job Applications'!$A$2:$A$1001,$H45))) | B45: =IF($H45="","",IF(INDEX('Job Applications'!$B$2:$B$1001,$H45)="","",INDEX('Job Applications'!$B$2:$B$1001,$H45))) | C45: =IF($H45="","",IF(INDEX('Job Applications'!$C$2:$C$1001,$H45)="","",INDEX('Job Applications'!$C$2:$C$1001,$H45))) | D45: =IF($H45="","",IF(INDEX('Job Applications'!$E$2:$E$1001,$H45)="","",INDEX('Job Applications'!$E$2:$E$1001,$H45))) | E45: =IF($H45="","",IF(INDEX('Job Applications'!$G$2:$G$1001,$H45)="","",INDEX('Job Applications'!$G$2:$G$1001,$H45))) | F45: =IF($H45="","",IF(INDEX('Job Applications'!$J$2:$J$1001,$H45)="","",INDEX('Job Applications'!$J$2:$J$1001,$H45))) | H45: =IFERROR(_xlfn.AGGREGATE(15,6,(ROW('Job Applications'!$K$2:$K$1001)-ROW('Job Applications'!$K$2)+1)/(('Job Applications'!$K$2:$K$1001=$B$3)*('Job Applications'!$B$2:$B$1001<>"")),ROWS($H$6:H45)),"")
A47: =IF($E$3=0,"No applications recorded for the selected week.","")

Sheet Lists
A1: Application Status | B1: Application Source | C1: Work Arrangement / Location | D1: Resume Version | E1: Role Category | F1: Resume Activity | G1: Recruiter Contact | H1: Interview Stage | I1: Feedback Type | J1: Salary Range | L1: CUSTOMIZE THE LIST TABLES
A2: Applied | B2: LinkedIn | C2: Remote | D2: Resume 1 | E2: Category 1 | F2: Not reported | G2: None reported | H2: None | I2: None reported | J2: Under $50,000
A3: Application Viewed | B3: Indeed | C3: Hybrid | D3: Resume 2 | E3: Category 2 | F3: Viewed | G3: Phone Call | H3: Phone Screen | I3: Form Rejection | J3: $50,000–$74,999 | L3: Each column A–J is a separate Excel Table.
A4: Resume Downloaded | B4: Company Website | C4: On-site | D4: Resume 3 | E4: Category 3 | F4: Downloaded | G4: Email | H4: First Interview | I4: Personalized Rejection | J4: $75,000–$99,999 | L4: Click a blank cell in rows 2–15 of a list and type your choice.
A5: Recruiter Contacted | B5: Recruiter | C5: Other | D5: Resume 4 | E5: 3 | F5: Viewed + Downloaded | G5: LinkedIn Message | H5: Second Interview | I5: Recruiter Feedback | J5: $100,000–$124,999 | L5: Dropdown menus update using their named list tables.
A6: Phone Screening | B6: Referral | C6: City, State | G6: Text Message | H6: Panel Interview | I6: Interview Feedback | J6: $125,000–$149,999 | L6: Blank cells in each table are available for new choices.
A7: Interview | B7: Networking | G7: Other | H7: Final Interview | I7: Offer Feedback | J7: $150,000–$174,999 | L7: Do not rename the table headers or table names.
A8: Second Interview | B8: Other | H8: Offer | I8: Other | J8: $175,000–$199,999 | L8: Use Page Layout > Themes to change theme colors.
A9: Final Interview | J9: $200,000+ | L9: Edit salary parameters in M3:M4 and M7:M10.
A10: Offer | J10: Not Disclosed | L10: Dashboard compares the entries listed in these tables.
A11: Rejected | J11: Negotiable
A12: Withdrawn
A13: Closed
